[2023-05-07T23:27:26.538+0000] {taskinstance.py:1125} INFO - Dependencies all met for dep_context=non-requeueable deps ti=<TaskInstance: ml_pipeline.machine_learning_task manual__2023-05-07T23:27:10.005743+00:00 [queued]>
[2023-05-07T23:27:26.544+0000] {taskinstance.py:1125} INFO - Dependencies all met for dep_context=requeueable deps ti=<TaskInstance: ml_pipeline.machine_learning_task manual__2023-05-07T23:27:10.005743+00:00 [queued]>
[2023-05-07T23:27:26.544+0000] {taskinstance.py:1331} INFO - Starting attempt 1 of 1
[2023-05-07T23:27:26.551+0000] {taskinstance.py:1350} INFO - Executing <Task(PythonOperator): machine_learning_task> on 2023-05-07 23:27:10.005743+00:00
[2023-05-07T23:27:26.559+0000] {standard_task_runner.py:57} INFO - Started process 126 to run task
[2023-05-07T23:27:26.563+0000] {standard_task_runner.py:84} INFO - Running: ['***', 'tasks', 'run', 'ml_pipeline', 'machine_learning_task', 'manual__2023-05-07T23:27:10.005743+00:00', '--job-id', '51', '--raw', '--subdir', 'DAGS_FOLDER/ml_pipeline.py', '--cfg-path', '/tmp/tmpwfed27w5']
[2023-05-07T23:27:26.566+0000] {standard_task_runner.py:85} INFO - Job 51: Subtask machine_learning_task
[2023-05-07T23:27:26.604+0000] {task_command.py:410} INFO - Running <TaskInstance: ml_pipeline.machine_learning_task manual__2023-05-07T23:27:10.005743+00:00 [running]> on host d2db9e8a0ded
[2023-05-07T23:27:26.658+0000] {taskinstance.py:1570} INFO - Exporting env vars: AIRFLOW_CTX_DAG_EMAIL='lequanghop844@gmail.com' AIRFLOW_CTX_DAG_OWNER='Felix Le' AIRFLOW_CTX_DAG_ID='ml_pipeline' AIRFLOW_CTX_TASK_ID='machine_learning_task' AIRFLOW_CTX_EXECUTION_DATE='2023-05-07T23:27:10.005743+00:00' AIRFLOW_CTX_TRY_NUMBER='1' AIRFLOW_CTX_DAG_RUN_ID='manual__2023-05-07T23:27:10.005743+00:00'
[2023-05-07T23:27:26.708+0000] {taskinstance.py:1847} ERROR - Task failed with exception
Traceback (most recent call last):
  File "/home/airflow/.local/lib/python3.7/site-packages/airflow/operators/python.py", line 181, in execute
    return_value = self.execute_callable()
  File "/home/airflow/.local/lib/python3.7/site-packages/airflow/operators/python.py", line 198, in execute_callable
    return self.python_callable(*self.op_args, **self.op_kwargs)
  File "/opt/airflow/dags/utils/fetching_best_model.py", line 27, in best_model_search
    features, target = fetch_data(df[0])
  File "/opt/airflow/dags/utils/fetch_data.py", line 9, in fetch_data
    df = df[['vol_moving_avg', 'adj_close_rolling_med', 'Volume']].values
  File "/home/airflow/.local/lib/python3.7/site-packages/pandas/core/frame.py", line 3464, in __getitem__
    indexer = self.loc._get_listlike_indexer(key, axis=1)[1]
  File "/home/airflow/.local/lib/python3.7/site-packages/pandas/core/indexing.py", line 1314, in _get_listlike_indexer
    self._validate_read_indexer(keyarr, indexer, axis)
  File "/home/airflow/.local/lib/python3.7/site-packages/pandas/core/indexing.py", line 1374, in _validate_read_indexer
    raise KeyError(f"None of [{key}] are in the [{axis_name}]")
KeyError: "None of [Index(['vol_moving_avg', 'adj_close_rolling_med', 'Volume'], dtype='object')] are in the [columns]"
[2023-05-07T23:27:26.719+0000] {taskinstance.py:1373} INFO - Marking task as FAILED. dag_id=ml_pipeline, task_id=machine_learning_task, execution_date=20230507T232710, start_date=20230507T232726, end_date=20230507T232726
[2023-05-07T23:27:26.725+0000] {standard_task_runner.py:109} ERROR - Failed to execute job 51 for task machine_learning_task ("None of [Index(['vol_moving_avg', 'adj_close_rolling_med', 'Volume'], dtype='object')] are in the [columns]"; 126)
[2023-05-07T23:27:26.783+0000] {local_task_job_runner.py:232} INFO - Task exited with return code 1
[2023-05-07T23:27:26.803+0000] {taskinstance.py:2674} INFO - 0 downstream tasks scheduled from follow-on schedule check
