[2023-05-29T06:20:33.463+0000] {taskinstance.py:1125} INFO - Dependencies all met for dep_context=non-requeueable deps ti=<TaskInstance: ml_pipeline.create_pg_connection_task manual__2023-05-29T06:20:23.358753+00:00 [queued]>
[2023-05-29T06:20:33.493+0000] {taskinstance.py:1125} INFO - Dependencies all met for dep_context=requeueable deps ti=<TaskInstance: ml_pipeline.create_pg_connection_task manual__2023-05-29T06:20:23.358753+00:00 [queued]>
[2023-05-29T06:20:33.496+0000] {taskinstance.py:1331} INFO - Starting attempt 1 of 1
[2023-05-29T06:20:33.525+0000] {taskinstance.py:1350} INFO - Executing <Task(PythonOperator): create_pg_connection_task> on 2023-05-29 06:20:23.358753+00:00
[2023-05-29T06:20:33.546+0000] {standard_task_runner.py:57} INFO - Started process 67 to run task
[2023-05-29T06:20:33.556+0000] {standard_task_runner.py:84} INFO - Running: ['***', 'tasks', 'run', 'ml_pipeline', 'create_pg_connection_task', 'manual__2023-05-29T06:20:23.358753+00:00', '--job-id', '3', '--raw', '--subdir', 'DAGS_FOLDER/ml_pipeline.py', '--cfg-path', '/tmp/tmpzc4br7zc']
[2023-05-29T06:20:33.564+0000] {standard_task_runner.py:85} INFO - Job 3: Subtask create_pg_connection_task
[2023-05-29T06:20:33.643+0000] {task_command.py:410} INFO - Running <TaskInstance: ml_pipeline.create_pg_connection_task manual__2023-05-29T06:20:23.358753+00:00 [running]> on host 84bce60ae612
[2023-05-29T06:20:33.785+0000] {taskinstance.py:1570} INFO - Exporting env vars: AIRFLOW_CTX_DAG_EMAIL='lequanghop844@gmail.com' AIRFLOW_CTX_DAG_OWNER='Felix Le' AIRFLOW_CTX_DAG_ID='ml_pipeline' AIRFLOW_CTX_TASK_ID='create_pg_connection_task' AIRFLOW_CTX_EXECUTION_DATE='2023-05-29T06:20:23.358753+00:00' AIRFLOW_CTX_TRY_NUMBER='1' AIRFLOW_CTX_DAG_RUN_ID='manual__2023-05-29T06:20:23.358753+00:00'
[2023-05-29T06:20:33.844+0000] {taskinstance.py:1847} ERROR - Task failed with exception
Traceback (most recent call last):
  File "/home/airflow/.local/lib/python3.7/site-packages/airflow/operators/python.py", line 181, in execute
    return_value = self.execute_callable()
  File "/home/airflow/.local/lib/python3.7/site-packages/airflow/operators/python.py", line 198, in execute_callable
    return self.python_callable(*self.op_args, **self.op_kwargs)
  File "/opt/airflow/dags/utils/create_connection.py", line 15, in create_connection_task
    existing_conn = BaseHook.get_connection(conn_id=conn_id)
  File "/home/airflow/.local/lib/python3.7/site-packages/airflow/hooks/base.py", line 72, in get_connection
    conn = Connection.get_connection_from_secrets(conn_id)
  File "/home/airflow/.local/lib/python3.7/site-packages/airflow/models/connection.py", line 434, in get_connection_from_secrets
    raise AirflowNotFoundException(f"The conn_id `{conn_id}` isn't defined")
airflow.exceptions.AirflowNotFoundException: The conn_id `pg_work_sample` isn't defined
[2023-05-29T06:20:33.857+0000] {taskinstance.py:1373} INFO - Marking task as FAILED. dag_id=ml_pipeline, task_id=create_pg_connection_task, execution_date=20230529T062023, start_date=20230529T062033, end_date=20230529T062033
[2023-05-29T06:20:33.879+0000] {standard_task_runner.py:109} ERROR - Failed to execute job 3 for task create_pg_connection_task (The conn_id `pg_work_sample` isn't defined; 67)
[2023-05-29T06:20:33.978+0000] {local_task_job_runner.py:232} INFO - Task exited with return code 1
[2023-05-29T06:20:34.070+0000] {taskinstance.py:2674} INFO - 0 downstream tasks scheduled from follow-on schedule check
