[2023-05-07T22:35:00.965+0000] {processor.py:156} INFO - Started process (PID=94) to work on /opt/airflow/dags/utils/fetching_best_model.py
[2023-05-07T22:35:00.966+0000] {processor.py:799} INFO - Processing file /opt/airflow/dags/utils/fetching_best_model.py for tasks to queue
[2023-05-07T22:35:00.968+0000] {logging_mixin.py:149} INFO - [2023-05-07T22:35:00.968+0000] {dagbag.py:541} INFO - Filling up the DagBag from /opt/airflow/dags/utils/fetching_best_model.py
[2023-05-07T22:35:05.989+0000] {logging_mixin.py:149} WARNING - /home/airflow/.local/lib/python3.7/site-packages/tensorflow_io/python/ops/__init__.py:98 UserWarning: unable to load libtensorflow_io_plugins.so: unable to open file: libtensorflow_io_plugins.so, from paths: ['/home/airflow/.local/lib/python3.7/site-packages/tensorflow_io/python/ops/libtensorflow_io_plugins.so']
caused by: ["[Errno 2] The file to load file system plugin from does not exist.: '/home/airflow/.local/lib/python3.7/site-packages/tensorflow_io/python/ops/libtensorflow_io_plugins.so'"]
[2023-05-07T22:35:05.998+0000] {logging_mixin.py:149} WARNING - /home/airflow/.local/lib/python3.7/site-packages/tensorflow_io/python/ops/__init__.py:104 UserWarning: file system plugins are not loaded: unable to open file: libtensorflow_io.so, from paths: ['/home/airflow/.local/lib/python3.7/site-packages/tensorflow_io/python/ops/libtensorflow_io.so']
caused by: ['/home/airflow/.local/lib/python3.7/site-packages/tensorflow_io/python/ops/libtensorflow_io.so: cannot open shared object file: No such file or directory']
[2023-05-07T22:35:06.293+0000] {processor.py:811} WARNING - No viable dags retrieved from /opt/airflow/dags/utils/fetching_best_model.py
[2023-05-07T22:35:06.314+0000] {processor.py:178} INFO - Processing /opt/airflow/dags/utils/fetching_best_model.py took 5.352 seconds
[2023-05-07T22:35:36.988+0000] {processor.py:156} INFO - Started process (PID=208) to work on /opt/airflow/dags/utils/fetching_best_model.py
[2023-05-07T22:35:36.990+0000] {processor.py:799} INFO - Processing file /opt/airflow/dags/utils/fetching_best_model.py for tasks to queue
[2023-05-07T22:35:36.991+0000] {logging_mixin.py:149} INFO - [2023-05-07T22:35:36.991+0000] {dagbag.py:541} INFO - Filling up the DagBag from /opt/airflow/dags/utils/fetching_best_model.py
[2023-05-07T22:35:38.972+0000] {logging_mixin.py:149} WARNING - /home/airflow/.local/lib/python3.7/site-packages/tensorflow_io/python/ops/__init__.py:98 UserWarning: unable to load libtensorflow_io_plugins.so: unable to open file: libtensorflow_io_plugins.so, from paths: ['/home/airflow/.local/lib/python3.7/site-packages/tensorflow_io/python/ops/libtensorflow_io_plugins.so']
caused by: ["[Errno 2] The file to load file system plugin from does not exist.: '/home/airflow/.local/lib/python3.7/site-packages/tensorflow_io/python/ops/libtensorflow_io_plugins.so'"]
[2023-05-07T22:35:38.976+0000] {logging_mixin.py:149} WARNING - /home/airflow/.local/lib/python3.7/site-packages/tensorflow_io/python/ops/__init__.py:104 UserWarning: file system plugins are not loaded: unable to open file: libtensorflow_io.so, from paths: ['/home/airflow/.local/lib/python3.7/site-packages/tensorflow_io/python/ops/libtensorflow_io.so']
caused by: ['/home/airflow/.local/lib/python3.7/site-packages/tensorflow_io/python/ops/libtensorflow_io.so: cannot open shared object file: No such file or directory']
[2023-05-07T22:35:39.175+0000] {processor.py:811} WARNING - No viable dags retrieved from /opt/airflow/dags/utils/fetching_best_model.py
[2023-05-07T22:35:39.190+0000] {processor.py:178} INFO - Processing /opt/airflow/dags/utils/fetching_best_model.py took 2.207 seconds
[2023-05-07T22:36:09.777+0000] {processor.py:156} INFO - Started process (PID=322) to work on /opt/airflow/dags/utils/fetching_best_model.py
[2023-05-07T22:36:09.778+0000] {processor.py:799} INFO - Processing file /opt/airflow/dags/utils/fetching_best_model.py for tasks to queue
[2023-05-07T22:36:09.779+0000] {logging_mixin.py:149} INFO - [2023-05-07T22:36:09.779+0000] {dagbag.py:541} INFO - Filling up the DagBag from /opt/airflow/dags/utils/fetching_best_model.py
[2023-05-07T22:36:11.403+0000] {logging_mixin.py:149} WARNING - /home/airflow/.local/lib/python3.7/site-packages/tensorflow_io/python/ops/__init__.py:98 UserWarning: unable to load libtensorflow_io_plugins.so: unable to open file: libtensorflow_io_plugins.so, from paths: ['/home/airflow/.local/lib/python3.7/site-packages/tensorflow_io/python/ops/libtensorflow_io_plugins.so']
caused by: ["[Errno 2] The file to load file system plugin from does not exist.: '/home/airflow/.local/lib/python3.7/site-packages/tensorflow_io/python/ops/libtensorflow_io_plugins.so'"]
[2023-05-07T22:36:11.405+0000] {logging_mixin.py:149} WARNING - /home/airflow/.local/lib/python3.7/site-packages/tensorflow_io/python/ops/__init__.py:104 UserWarning: file system plugins are not loaded: unable to open file: libtensorflow_io.so, from paths: ['/home/airflow/.local/lib/python3.7/site-packages/tensorflow_io/python/ops/libtensorflow_io.so']
caused by: ['/home/airflow/.local/lib/python3.7/site-packages/tensorflow_io/python/ops/libtensorflow_io.so: cannot open shared object file: No such file or directory']
[2023-05-07T22:36:11.492+0000] {processor.py:811} WARNING - No viable dags retrieved from /opt/airflow/dags/utils/fetching_best_model.py
[2023-05-07T22:36:11.504+0000] {processor.py:178} INFO - Processing /opt/airflow/dags/utils/fetching_best_model.py took 1.730 seconds
[2023-05-07T22:36:41.663+0000] {processor.py:156} INFO - Started process (PID=444) to work on /opt/airflow/dags/utils/fetching_best_model.py
[2023-05-07T22:36:41.664+0000] {processor.py:799} INFO - Processing file /opt/airflow/dags/utils/fetching_best_model.py for tasks to queue
[2023-05-07T22:36:41.665+0000] {logging_mixin.py:149} INFO - [2023-05-07T22:36:41.665+0000] {dagbag.py:541} INFO - Filling up the DagBag from /opt/airflow/dags/utils/fetching_best_model.py
[2023-05-07T22:36:43.559+0000] {logging_mixin.py:149} WARNING - /home/airflow/.local/lib/python3.7/site-packages/tensorflow_io/python/ops/__init__.py:98 UserWarning: unable to load libtensorflow_io_plugins.so: unable to open file: libtensorflow_io_plugins.so, from paths: ['/home/airflow/.local/lib/python3.7/site-packages/tensorflow_io/python/ops/libtensorflow_io_plugins.so']
caused by: ["[Errno 2] The file to load file system plugin from does not exist.: '/home/airflow/.local/lib/python3.7/site-packages/tensorflow_io/python/ops/libtensorflow_io_plugins.so'"]
[2023-05-07T22:36:43.562+0000] {logging_mixin.py:149} WARNING - /home/airflow/.local/lib/python3.7/site-packages/tensorflow_io/python/ops/__init__.py:104 UserWarning: file system plugins are not loaded: unable to open file: libtensorflow_io.so, from paths: ['/home/airflow/.local/lib/python3.7/site-packages/tensorflow_io/python/ops/libtensorflow_io.so']
caused by: ['/home/airflow/.local/lib/python3.7/site-packages/tensorflow_io/python/ops/libtensorflow_io.so: cannot open shared object file: No such file or directory']
[2023-05-07T22:36:43.709+0000] {processor.py:811} WARNING - No viable dags retrieved from /opt/airflow/dags/utils/fetching_best_model.py
[2023-05-07T22:36:43.722+0000] {processor.py:178} INFO - Processing /opt/airflow/dags/utils/fetching_best_model.py took 2.062 seconds
[2023-05-07T22:37:13.978+0000] {processor.py:156} INFO - Started process (PID=576) to work on /opt/airflow/dags/utils/fetching_best_model.py
[2023-05-07T22:37:13.980+0000] {processor.py:799} INFO - Processing file /opt/airflow/dags/utils/fetching_best_model.py for tasks to queue
[2023-05-07T22:37:13.981+0000] {logging_mixin.py:149} INFO - [2023-05-07T22:37:13.981+0000] {dagbag.py:541} INFO - Filling up the DagBag from /opt/airflow/dags/utils/fetching_best_model.py
[2023-05-07T22:37:15.679+0000] {logging_mixin.py:149} WARNING - /home/airflow/.local/lib/python3.7/site-packages/tensorflow_io/python/ops/__init__.py:98 UserWarning: unable to load libtensorflow_io_plugins.so: unable to open file: libtensorflow_io_plugins.so, from paths: ['/home/airflow/.local/lib/python3.7/site-packages/tensorflow_io/python/ops/libtensorflow_io_plugins.so']
caused by: ["[Errno 2] The file to load file system plugin from does not exist.: '/home/airflow/.local/lib/python3.7/site-packages/tensorflow_io/python/ops/libtensorflow_io_plugins.so'"]
[2023-05-07T22:37:15.682+0000] {logging_mixin.py:149} WARNING - /home/airflow/.local/lib/python3.7/site-packages/tensorflow_io/python/ops/__init__.py:104 UserWarning: file system plugins are not loaded: unable to open file: libtensorflow_io.so, from paths: ['/home/airflow/.local/lib/python3.7/site-packages/tensorflow_io/python/ops/libtensorflow_io.so']
caused by: ['/home/airflow/.local/lib/python3.7/site-packages/tensorflow_io/python/ops/libtensorflow_io.so: cannot open shared object file: No such file or directory']
[2023-05-07T22:37:15.767+0000] {processor.py:811} WARNING - No viable dags retrieved from /opt/airflow/dags/utils/fetching_best_model.py
[2023-05-07T22:37:15.778+0000] {processor.py:178} INFO - Processing /opt/airflow/dags/utils/fetching_best_model.py took 1.803 seconds
[2023-05-07T22:37:45.905+0000] {processor.py:156} INFO - Started process (PID=735) to work on /opt/airflow/dags/utils/fetching_best_model.py
[2023-05-07T22:37:45.907+0000] {processor.py:799} INFO - Processing file /opt/airflow/dags/utils/fetching_best_model.py for tasks to queue
[2023-05-07T22:37:45.908+0000] {logging_mixin.py:149} INFO - [2023-05-07T22:37:45.908+0000] {dagbag.py:541} INFO - Filling up the DagBag from /opt/airflow/dags/utils/fetching_best_model.py
[2023-05-07T22:37:48.064+0000] {logging_mixin.py:149} WARNING - /home/airflow/.local/lib/python3.7/site-packages/tensorflow_io/python/ops/__init__.py:98 UserWarning: unable to load libtensorflow_io_plugins.so: unable to open file: libtensorflow_io_plugins.so, from paths: ['/home/airflow/.local/lib/python3.7/site-packages/tensorflow_io/python/ops/libtensorflow_io_plugins.so']
caused by: ["[Errno 2] The file to load file system plugin from does not exist.: '/home/airflow/.local/lib/python3.7/site-packages/tensorflow_io/python/ops/libtensorflow_io_plugins.so'"]
[2023-05-07T22:37:48.072+0000] {logging_mixin.py:149} WARNING - /home/airflow/.local/lib/python3.7/site-packages/tensorflow_io/python/ops/__init__.py:104 UserWarning: file system plugins are not loaded: unable to open file: libtensorflow_io.so, from paths: ['/home/airflow/.local/lib/python3.7/site-packages/tensorflow_io/python/ops/libtensorflow_io.so']
caused by: ['/home/airflow/.local/lib/python3.7/site-packages/tensorflow_io/python/ops/libtensorflow_io.so: cannot open shared object file: No such file or directory']
[2023-05-07T22:37:48.188+0000] {processor.py:811} WARNING - No viable dags retrieved from /opt/airflow/dags/utils/fetching_best_model.py
[2023-05-07T22:37:48.199+0000] {processor.py:178} INFO - Processing /opt/airflow/dags/utils/fetching_best_model.py took 2.297 seconds
[2023-05-07T22:38:18.417+0000] {processor.py:156} INFO - Started process (PID=862) to work on /opt/airflow/dags/utils/fetching_best_model.py
[2023-05-07T22:38:18.419+0000] {processor.py:799} INFO - Processing file /opt/airflow/dags/utils/fetching_best_model.py for tasks to queue
[2023-05-07T22:38:18.420+0000] {logging_mixin.py:149} INFO - [2023-05-07T22:38:18.420+0000] {dagbag.py:541} INFO - Filling up the DagBag from /opt/airflow/dags/utils/fetching_best_model.py
[2023-05-07T22:38:20.111+0000] {logging_mixin.py:149} WARNING - /home/airflow/.local/lib/python3.7/site-packages/tensorflow_io/python/ops/__init__.py:98 UserWarning: unable to load libtensorflow_io_plugins.so: unable to open file: libtensorflow_io_plugins.so, from paths: ['/home/airflow/.local/lib/python3.7/site-packages/tensorflow_io/python/ops/libtensorflow_io_plugins.so']
caused by: ["[Errno 2] The file to load file system plugin from does not exist.: '/home/airflow/.local/lib/python3.7/site-packages/tensorflow_io/python/ops/libtensorflow_io_plugins.so'"]
[2023-05-07T22:38:20.113+0000] {logging_mixin.py:149} WARNING - /home/airflow/.local/lib/python3.7/site-packages/tensorflow_io/python/ops/__init__.py:104 UserWarning: file system plugins are not loaded: unable to open file: libtensorflow_io.so, from paths: ['/home/airflow/.local/lib/python3.7/site-packages/tensorflow_io/python/ops/libtensorflow_io.so']
caused by: ['/home/airflow/.local/lib/python3.7/site-packages/tensorflow_io/python/ops/libtensorflow_io.so: cannot open shared object file: No such file or directory']
[2023-05-07T22:38:20.217+0000] {processor.py:811} WARNING - No viable dags retrieved from /opt/airflow/dags/utils/fetching_best_model.py
[2023-05-07T22:38:20.228+0000] {processor.py:178} INFO - Processing /opt/airflow/dags/utils/fetching_best_model.py took 1.814 seconds
[2023-05-07T22:38:50.577+0000] {processor.py:156} INFO - Started process (PID=991) to work on /opt/airflow/dags/utils/fetching_best_model.py
[2023-05-07T22:38:50.579+0000] {processor.py:799} INFO - Processing file /opt/airflow/dags/utils/fetching_best_model.py for tasks to queue
[2023-05-07T22:38:50.579+0000] {logging_mixin.py:149} INFO - [2023-05-07T22:38:50.579+0000] {dagbag.py:541} INFO - Filling up the DagBag from /opt/airflow/dags/utils/fetching_best_model.py
[2023-05-07T22:38:52.178+0000] {logging_mixin.py:149} WARNING - /home/airflow/.local/lib/python3.7/site-packages/tensorflow_io/python/ops/__init__.py:98 UserWarning: unable to load libtensorflow_io_plugins.so: unable to open file: libtensorflow_io_plugins.so, from paths: ['/home/airflow/.local/lib/python3.7/site-packages/tensorflow_io/python/ops/libtensorflow_io_plugins.so']
caused by: ["[Errno 2] The file to load file system plugin from does not exist.: '/home/airflow/.local/lib/python3.7/site-packages/tensorflow_io/python/ops/libtensorflow_io_plugins.so'"]
[2023-05-07T22:38:52.180+0000] {logging_mixin.py:149} WARNING - /home/airflow/.local/lib/python3.7/site-packages/tensorflow_io/python/ops/__init__.py:104 UserWarning: file system plugins are not loaded: unable to open file: libtensorflow_io.so, from paths: ['/home/airflow/.local/lib/python3.7/site-packages/tensorflow_io/python/ops/libtensorflow_io.so']
caused by: ['/home/airflow/.local/lib/python3.7/site-packages/tensorflow_io/python/ops/libtensorflow_io.so: cannot open shared object file: No such file or directory']
[2023-05-07T22:38:52.272+0000] {processor.py:811} WARNING - No viable dags retrieved from /opt/airflow/dags/utils/fetching_best_model.py
[2023-05-07T22:38:52.282+0000] {processor.py:178} INFO - Processing /opt/airflow/dags/utils/fetching_best_model.py took 1.710 seconds
[2023-05-07T22:39:22.390+0000] {processor.py:156} INFO - Started process (PID=1113) to work on /opt/airflow/dags/utils/fetching_best_model.py
[2023-05-07T22:39:22.392+0000] {processor.py:799} INFO - Processing file /opt/airflow/dags/utils/fetching_best_model.py for tasks to queue
[2023-05-07T22:39:22.394+0000] {logging_mixin.py:149} INFO - [2023-05-07T22:39:22.394+0000] {dagbag.py:541} INFO - Filling up the DagBag from /opt/airflow/dags/utils/fetching_best_model.py
[2023-05-07T22:39:24.160+0000] {logging_mixin.py:149} WARNING - /home/airflow/.local/lib/python3.7/site-packages/tensorflow_io/python/ops/__init__.py:98 UserWarning: unable to load libtensorflow_io_plugins.so: unable to open file: libtensorflow_io_plugins.so, from paths: ['/home/airflow/.local/lib/python3.7/site-packages/tensorflow_io/python/ops/libtensorflow_io_plugins.so']
caused by: ["[Errno 2] The file to load file system plugin from does not exist.: '/home/airflow/.local/lib/python3.7/site-packages/tensorflow_io/python/ops/libtensorflow_io_plugins.so'"]
[2023-05-07T22:39:24.173+0000] {logging_mixin.py:149} WARNING - /home/airflow/.local/lib/python3.7/site-packages/tensorflow_io/python/ops/__init__.py:104 UserWarning: file system plugins are not loaded: unable to open file: libtensorflow_io.so, from paths: ['/home/airflow/.local/lib/python3.7/site-packages/tensorflow_io/python/ops/libtensorflow_io.so']
caused by: ['/home/airflow/.local/lib/python3.7/site-packages/tensorflow_io/python/ops/libtensorflow_io.so: cannot open shared object file: No such file or directory']
[2023-05-07T22:39:24.308+0000] {processor.py:811} WARNING - No viable dags retrieved from /opt/airflow/dags/utils/fetching_best_model.py
[2023-05-07T22:39:24.320+0000] {processor.py:178} INFO - Processing /opt/airflow/dags/utils/fetching_best_model.py took 1.936 seconds
[2023-05-07T22:39:54.523+0000] {processor.py:156} INFO - Started process (PID=1251) to work on /opt/airflow/dags/utils/fetching_best_model.py
[2023-05-07T22:39:54.524+0000] {processor.py:799} INFO - Processing file /opt/airflow/dags/utils/fetching_best_model.py for tasks to queue
[2023-05-07T22:39:54.525+0000] {logging_mixin.py:149} INFO - [2023-05-07T22:39:54.525+0000] {dagbag.py:541} INFO - Filling up the DagBag from /opt/airflow/dags/utils/fetching_best_model.py
[2023-05-07T22:39:56.221+0000] {logging_mixin.py:149} WARNING - /home/airflow/.local/lib/python3.7/site-packages/tensorflow_io/python/ops/__init__.py:98 UserWarning: unable to load libtensorflow_io_plugins.so: unable to open file: libtensorflow_io_plugins.so, from paths: ['/home/airflow/.local/lib/python3.7/site-packages/tensorflow_io/python/ops/libtensorflow_io_plugins.so']
caused by: ["[Errno 2] The file to load file system plugin from does not exist.: '/home/airflow/.local/lib/python3.7/site-packages/tensorflow_io/python/ops/libtensorflow_io_plugins.so'"]
[2023-05-07T22:39:56.223+0000] {logging_mixin.py:149} WARNING - /home/airflow/.local/lib/python3.7/site-packages/tensorflow_io/python/ops/__init__.py:104 UserWarning: file system plugins are not loaded: unable to open file: libtensorflow_io.so, from paths: ['/home/airflow/.local/lib/python3.7/site-packages/tensorflow_io/python/ops/libtensorflow_io.so']
caused by: ['/home/airflow/.local/lib/python3.7/site-packages/tensorflow_io/python/ops/libtensorflow_io.so: cannot open shared object file: No such file or directory']
[2023-05-07T22:39:56.350+0000] {processor.py:811} WARNING - No viable dags retrieved from /opt/airflow/dags/utils/fetching_best_model.py
[2023-05-07T22:39:56.362+0000] {processor.py:178} INFO - Processing /opt/airflow/dags/utils/fetching_best_model.py took 1.842 seconds
[2023-05-07T22:40:26.476+0000] {processor.py:156} INFO - Started process (PID=1392) to work on /opt/airflow/dags/utils/fetching_best_model.py
[2023-05-07T22:40:26.478+0000] {processor.py:799} INFO - Processing file /opt/airflow/dags/utils/fetching_best_model.py for tasks to queue
[2023-05-07T22:40:26.478+0000] {logging_mixin.py:149} INFO - [2023-05-07T22:40:26.478+0000] {dagbag.py:541} INFO - Filling up the DagBag from /opt/airflow/dags/utils/fetching_best_model.py
[2023-05-07T22:40:28.027+0000] {logging_mixin.py:149} WARNING - /home/airflow/.local/lib/python3.7/site-packages/tensorflow_io/python/ops/__init__.py:98 UserWarning: unable to load libtensorflow_io_plugins.so: unable to open file: libtensorflow_io_plugins.so, from paths: ['/home/airflow/.local/lib/python3.7/site-packages/tensorflow_io/python/ops/libtensorflow_io_plugins.so']
caused by: ["[Errno 2] The file to load file system plugin from does not exist.: '/home/airflow/.local/lib/python3.7/site-packages/tensorflow_io/python/ops/libtensorflow_io_plugins.so'"]
[2023-05-07T22:40:28.030+0000] {logging_mixin.py:149} WARNING - /home/airflow/.local/lib/python3.7/site-packages/tensorflow_io/python/ops/__init__.py:104 UserWarning: file system plugins are not loaded: unable to open file: libtensorflow_io.so, from paths: ['/home/airflow/.local/lib/python3.7/site-packages/tensorflow_io/python/ops/libtensorflow_io.so']
caused by: ['/home/airflow/.local/lib/python3.7/site-packages/tensorflow_io/python/ops/libtensorflow_io.so: cannot open shared object file: No such file or directory']
[2023-05-07T22:40:28.130+0000] {processor.py:811} WARNING - No viable dags retrieved from /opt/airflow/dags/utils/fetching_best_model.py
[2023-05-07T22:40:28.142+0000] {processor.py:178} INFO - Processing /opt/airflow/dags/utils/fetching_best_model.py took 1.669 seconds
[2023-05-07T22:44:17.475+0000] {processor.py:156} INFO - Started process (PID=111) to work on /opt/airflow/dags/utils/fetching_best_model.py
[2023-05-07T22:44:17.477+0000] {processor.py:799} INFO - Processing file /opt/airflow/dags/utils/fetching_best_model.py for tasks to queue
[2023-05-07T22:44:17.479+0000] {logging_mixin.py:149} INFO - [2023-05-07T22:44:17.478+0000] {dagbag.py:541} INFO - Filling up the DagBag from /opt/airflow/dags/utils/fetching_best_model.py
[2023-05-07T22:44:19.837+0000] {logging_mixin.py:149} WARNING - /home/airflow/.local/lib/python3.7/site-packages/tensorflow_io/python/ops/__init__.py:98 UserWarning: unable to load libtensorflow_io_plugins.so: unable to open file: libtensorflow_io_plugins.so, from paths: ['/home/airflow/.local/lib/python3.7/site-packages/tensorflow_io/python/ops/libtensorflow_io_plugins.so']
caused by: ["[Errno 2] The file to load file system plugin from does not exist.: '/home/airflow/.local/lib/python3.7/site-packages/tensorflow_io/python/ops/libtensorflow_io_plugins.so'"]
[2023-05-07T22:44:19.840+0000] {logging_mixin.py:149} WARNING - /home/airflow/.local/lib/python3.7/site-packages/tensorflow_io/python/ops/__init__.py:104 UserWarning: file system plugins are not loaded: unable to open file: libtensorflow_io.so, from paths: ['/home/airflow/.local/lib/python3.7/site-packages/tensorflow_io/python/ops/libtensorflow_io.so']
caused by: ['/home/airflow/.local/lib/python3.7/site-packages/tensorflow_io/python/ops/libtensorflow_io.so: cannot open shared object file: No such file or directory']
[2023-05-07T22:44:19.976+0000] {processor.py:811} WARNING - No viable dags retrieved from /opt/airflow/dags/utils/fetching_best_model.py
[2023-05-07T22:44:19.990+0000] {processor.py:178} INFO - Processing /opt/airflow/dags/utils/fetching_best_model.py took 2.518 seconds
[2023-05-07T22:44:50.284+0000] {processor.py:156} INFO - Started process (PID=255) to work on /opt/airflow/dags/utils/fetching_best_model.py
[2023-05-07T22:44:50.286+0000] {processor.py:799} INFO - Processing file /opt/airflow/dags/utils/fetching_best_model.py for tasks to queue
[2023-05-07T22:44:50.288+0000] {logging_mixin.py:149} INFO - [2023-05-07T22:44:50.287+0000] {dagbag.py:541} INFO - Filling up the DagBag from /opt/airflow/dags/utils/fetching_best_model.py
[2023-05-07T22:44:52.399+0000] {logging_mixin.py:149} WARNING - /home/airflow/.local/lib/python3.7/site-packages/tensorflow_io/python/ops/__init__.py:98 UserWarning: unable to load libtensorflow_io_plugins.so: unable to open file: libtensorflow_io_plugins.so, from paths: ['/home/airflow/.local/lib/python3.7/site-packages/tensorflow_io/python/ops/libtensorflow_io_plugins.so']
caused by: ["[Errno 2] The file to load file system plugin from does not exist.: '/home/airflow/.local/lib/python3.7/site-packages/tensorflow_io/python/ops/libtensorflow_io_plugins.so'"]
[2023-05-07T22:44:52.402+0000] {logging_mixin.py:149} WARNING - /home/airflow/.local/lib/python3.7/site-packages/tensorflow_io/python/ops/__init__.py:104 UserWarning: file system plugins are not loaded: unable to open file: libtensorflow_io.so, from paths: ['/home/airflow/.local/lib/python3.7/site-packages/tensorflow_io/python/ops/libtensorflow_io.so']
caused by: ['/home/airflow/.local/lib/python3.7/site-packages/tensorflow_io/python/ops/libtensorflow_io.so: cannot open shared object file: No such file or directory']
[2023-05-07T22:44:52.639+0000] {processor.py:811} WARNING - No viable dags retrieved from /opt/airflow/dags/utils/fetching_best_model.py
[2023-05-07T22:44:52.652+0000] {processor.py:178} INFO - Processing /opt/airflow/dags/utils/fetching_best_model.py took 2.375 seconds
[2023-05-07T22:45:23.075+0000] {processor.py:156} INFO - Started process (PID=383) to work on /opt/airflow/dags/utils/fetching_best_model.py
[2023-05-07T22:45:23.077+0000] {processor.py:799} INFO - Processing file /opt/airflow/dags/utils/fetching_best_model.py for tasks to queue
[2023-05-07T22:45:23.079+0000] {logging_mixin.py:149} INFO - [2023-05-07T22:45:23.079+0000] {dagbag.py:541} INFO - Filling up the DagBag from /opt/airflow/dags/utils/fetching_best_model.py
[2023-05-07T22:45:24.968+0000] {logging_mixin.py:149} WARNING - /home/airflow/.local/lib/python3.7/site-packages/tensorflow_io/python/ops/__init__.py:98 UserWarning: unable to load libtensorflow_io_plugins.so: unable to open file: libtensorflow_io_plugins.so, from paths: ['/home/airflow/.local/lib/python3.7/site-packages/tensorflow_io/python/ops/libtensorflow_io_plugins.so']
caused by: ["[Errno 2] The file to load file system plugin from does not exist.: '/home/airflow/.local/lib/python3.7/site-packages/tensorflow_io/python/ops/libtensorflow_io_plugins.so'"]
[2023-05-07T22:45:24.971+0000] {logging_mixin.py:149} WARNING - /home/airflow/.local/lib/python3.7/site-packages/tensorflow_io/python/ops/__init__.py:104 UserWarning: file system plugins are not loaded: unable to open file: libtensorflow_io.so, from paths: ['/home/airflow/.local/lib/python3.7/site-packages/tensorflow_io/python/ops/libtensorflow_io.so']
caused by: ['/home/airflow/.local/lib/python3.7/site-packages/tensorflow_io/python/ops/libtensorflow_io.so: cannot open shared object file: No such file or directory']
[2023-05-07T22:45:25.074+0000] {processor.py:811} WARNING - No viable dags retrieved from /opt/airflow/dags/utils/fetching_best_model.py
[2023-05-07T22:45:25.085+0000] {processor.py:178} INFO - Processing /opt/airflow/dags/utils/fetching_best_model.py took 2.017 seconds
[2023-05-07T22:45:55.447+0000] {processor.py:156} INFO - Started process (PID=508) to work on /opt/airflow/dags/utils/fetching_best_model.py
[2023-05-07T22:45:55.450+0000] {processor.py:799} INFO - Processing file /opt/airflow/dags/utils/fetching_best_model.py for tasks to queue
[2023-05-07T22:45:55.452+0000] {logging_mixin.py:149} INFO - [2023-05-07T22:45:55.452+0000] {dagbag.py:541} INFO - Filling up the DagBag from /opt/airflow/dags/utils/fetching_best_model.py
[2023-05-07T22:45:57.465+0000] {logging_mixin.py:149} WARNING - /home/airflow/.local/lib/python3.7/site-packages/tensorflow_io/python/ops/__init__.py:98 UserWarning: unable to load libtensorflow_io_plugins.so: unable to open file: libtensorflow_io_plugins.so, from paths: ['/home/airflow/.local/lib/python3.7/site-packages/tensorflow_io/python/ops/libtensorflow_io_plugins.so']
caused by: ["[Errno 2] The file to load file system plugin from does not exist.: '/home/airflow/.local/lib/python3.7/site-packages/tensorflow_io/python/ops/libtensorflow_io_plugins.so'"]
[2023-05-07T22:45:57.475+0000] {logging_mixin.py:149} WARNING - /home/airflow/.local/lib/python3.7/site-packages/tensorflow_io/python/ops/__init__.py:104 UserWarning: file system plugins are not loaded: unable to open file: libtensorflow_io.so, from paths: ['/home/airflow/.local/lib/python3.7/site-packages/tensorflow_io/python/ops/libtensorflow_io.so']
caused by: ['/home/airflow/.local/lib/python3.7/site-packages/tensorflow_io/python/ops/libtensorflow_io.so: cannot open shared object file: No such file or directory']
[2023-05-07T22:45:57.606+0000] {processor.py:811} WARNING - No viable dags retrieved from /opt/airflow/dags/utils/fetching_best_model.py
[2023-05-07T22:45:57.621+0000] {processor.py:178} INFO - Processing /opt/airflow/dags/utils/fetching_best_model.py took 2.181 seconds
[2023-05-07T22:46:27.978+0000] {processor.py:156} INFO - Started process (PID=647) to work on /opt/airflow/dags/utils/fetching_best_model.py
[2023-05-07T22:46:27.979+0000] {processor.py:799} INFO - Processing file /opt/airflow/dags/utils/fetching_best_model.py for tasks to queue
[2023-05-07T22:46:27.980+0000] {logging_mixin.py:149} INFO - [2023-05-07T22:46:27.980+0000] {dagbag.py:541} INFO - Filling up the DagBag from /opt/airflow/dags/utils/fetching_best_model.py
[2023-05-07T22:46:29.669+0000] {logging_mixin.py:149} WARNING - /home/airflow/.local/lib/python3.7/site-packages/tensorflow_io/python/ops/__init__.py:98 UserWarning: unable to load libtensorflow_io_plugins.so: unable to open file: libtensorflow_io_plugins.so, from paths: ['/home/airflow/.local/lib/python3.7/site-packages/tensorflow_io/python/ops/libtensorflow_io_plugins.so']
caused by: ["[Errno 2] The file to load file system plugin from does not exist.: '/home/airflow/.local/lib/python3.7/site-packages/tensorflow_io/python/ops/libtensorflow_io_plugins.so'"]
[2023-05-07T22:46:29.671+0000] {logging_mixin.py:149} WARNING - /home/airflow/.local/lib/python3.7/site-packages/tensorflow_io/python/ops/__init__.py:104 UserWarning: file system plugins are not loaded: unable to open file: libtensorflow_io.so, from paths: ['/home/airflow/.local/lib/python3.7/site-packages/tensorflow_io/python/ops/libtensorflow_io.so']
caused by: ['/home/airflow/.local/lib/python3.7/site-packages/tensorflow_io/python/ops/libtensorflow_io.so: cannot open shared object file: No such file or directory']
[2023-05-07T22:46:29.918+0000] {processor.py:811} WARNING - No viable dags retrieved from /opt/airflow/dags/utils/fetching_best_model.py
[2023-05-07T22:46:29.948+0000] {processor.py:178} INFO - Processing /opt/airflow/dags/utils/fetching_best_model.py took 1.973 seconds
[2023-05-07T22:47:00.422+0000] {processor.py:156} INFO - Started process (PID=761) to work on /opt/airflow/dags/utils/fetching_best_model.py
[2023-05-07T22:47:00.424+0000] {processor.py:799} INFO - Processing file /opt/airflow/dags/utils/fetching_best_model.py for tasks to queue
[2023-05-07T22:47:00.426+0000] {logging_mixin.py:149} INFO - [2023-05-07T22:47:00.425+0000] {dagbag.py:541} INFO - Filling up the DagBag from /opt/airflow/dags/utils/fetching_best_model.py
[2023-05-07T22:47:01.976+0000] {logging_mixin.py:149} WARNING - /home/airflow/.local/lib/python3.7/site-packages/tensorflow_io/python/ops/__init__.py:98 UserWarning: unable to load libtensorflow_io_plugins.so: unable to open file: libtensorflow_io_plugins.so, from paths: ['/home/airflow/.local/lib/python3.7/site-packages/tensorflow_io/python/ops/libtensorflow_io_plugins.so']
caused by: ["[Errno 2] The file to load file system plugin from does not exist.: '/home/airflow/.local/lib/python3.7/site-packages/tensorflow_io/python/ops/libtensorflow_io_plugins.so'"]
[2023-05-07T22:47:01.978+0000] {logging_mixin.py:149} WARNING - /home/airflow/.local/lib/python3.7/site-packages/tensorflow_io/python/ops/__init__.py:104 UserWarning: file system plugins are not loaded: unable to open file: libtensorflow_io.so, from paths: ['/home/airflow/.local/lib/python3.7/site-packages/tensorflow_io/python/ops/libtensorflow_io.so']
caused by: ['/home/airflow/.local/lib/python3.7/site-packages/tensorflow_io/python/ops/libtensorflow_io.so: cannot open shared object file: No such file or directory']
[2023-05-07T22:47:02.054+0000] {processor.py:811} WARNING - No viable dags retrieved from /opt/airflow/dags/utils/fetching_best_model.py
[2023-05-07T22:47:02.064+0000] {processor.py:178} INFO - Processing /opt/airflow/dags/utils/fetching_best_model.py took 1.646 seconds
[2023-05-07T22:47:32.314+0000] {processor.py:156} INFO - Started process (PID=875) to work on /opt/airflow/dags/utils/fetching_best_model.py
[2023-05-07T22:47:32.317+0000] {processor.py:799} INFO - Processing file /opt/airflow/dags/utils/fetching_best_model.py for tasks to queue
[2023-05-07T22:47:32.320+0000] {logging_mixin.py:149} INFO - [2023-05-07T22:47:32.319+0000] {dagbag.py:541} INFO - Filling up the DagBag from /opt/airflow/dags/utils/fetching_best_model.py
[2023-05-07T22:47:34.373+0000] {logging_mixin.py:149} WARNING - /home/airflow/.local/lib/python3.7/site-packages/tensorflow_io/python/ops/__init__.py:98 UserWarning: unable to load libtensorflow_io_plugins.so: unable to open file: libtensorflow_io_plugins.so, from paths: ['/home/airflow/.local/lib/python3.7/site-packages/tensorflow_io/python/ops/libtensorflow_io_plugins.so']
caused by: ["[Errno 2] The file to load file system plugin from does not exist.: '/home/airflow/.local/lib/python3.7/site-packages/tensorflow_io/python/ops/libtensorflow_io_plugins.so'"]
[2023-05-07T22:47:34.377+0000] {logging_mixin.py:149} WARNING - /home/airflow/.local/lib/python3.7/site-packages/tensorflow_io/python/ops/__init__.py:104 UserWarning: file system plugins are not loaded: unable to open file: libtensorflow_io.so, from paths: ['/home/airflow/.local/lib/python3.7/site-packages/tensorflow_io/python/ops/libtensorflow_io.so']
caused by: ['/home/airflow/.local/lib/python3.7/site-packages/tensorflow_io/python/ops/libtensorflow_io.so: cannot open shared object file: No such file or directory']
[2023-05-07T22:47:34.474+0000] {processor.py:811} WARNING - No viable dags retrieved from /opt/airflow/dags/utils/fetching_best_model.py
[2023-05-07T22:47:34.488+0000] {processor.py:178} INFO - Processing /opt/airflow/dags/utils/fetching_best_model.py took 2.178 seconds
[2023-05-07T22:48:05.333+0000] {processor.py:156} INFO - Started process (PID=989) to work on /opt/airflow/dags/utils/fetching_best_model.py
[2023-05-07T22:48:05.335+0000] {processor.py:799} INFO - Processing file /opt/airflow/dags/utils/fetching_best_model.py for tasks to queue
[2023-05-07T22:48:05.336+0000] {logging_mixin.py:149} INFO - [2023-05-07T22:48:05.336+0000] {dagbag.py:541} INFO - Filling up the DagBag from /opt/airflow/dags/utils/fetching_best_model.py
[2023-05-07T22:48:06.842+0000] {logging_mixin.py:149} WARNING - /home/airflow/.local/lib/python3.7/site-packages/tensorflow_io/python/ops/__init__.py:98 UserWarning: unable to load libtensorflow_io_plugins.so: unable to open file: libtensorflow_io_plugins.so, from paths: ['/home/airflow/.local/lib/python3.7/site-packages/tensorflow_io/python/ops/libtensorflow_io_plugins.so']
caused by: ["[Errno 2] The file to load file system plugin from does not exist.: '/home/airflow/.local/lib/python3.7/site-packages/tensorflow_io/python/ops/libtensorflow_io_plugins.so'"]
[2023-05-07T22:48:06.845+0000] {logging_mixin.py:149} WARNING - /home/airflow/.local/lib/python3.7/site-packages/tensorflow_io/python/ops/__init__.py:104 UserWarning: file system plugins are not loaded: unable to open file: libtensorflow_io.so, from paths: ['/home/airflow/.local/lib/python3.7/site-packages/tensorflow_io/python/ops/libtensorflow_io.so']
caused by: ['/home/airflow/.local/lib/python3.7/site-packages/tensorflow_io/python/ops/libtensorflow_io.so: cannot open shared object file: No such file or directory']
[2023-05-07T22:48:06.933+0000] {processor.py:811} WARNING - No viable dags retrieved from /opt/airflow/dags/utils/fetching_best_model.py
[2023-05-07T22:48:06.943+0000] {processor.py:178} INFO - Processing /opt/airflow/dags/utils/fetching_best_model.py took 1.615 seconds
[2023-05-07T22:51:35.028+0000] {processor.py:156} INFO - Started process (PID=111) to work on /opt/airflow/dags/utils/fetching_best_model.py
[2023-05-07T22:51:35.031+0000] {processor.py:799} INFO - Processing file /opt/airflow/dags/utils/fetching_best_model.py for tasks to queue
[2023-05-07T22:51:35.032+0000] {logging_mixin.py:149} INFO - [2023-05-07T22:51:35.032+0000] {dagbag.py:541} INFO - Filling up the DagBag from /opt/airflow/dags/utils/fetching_best_model.py
[2023-05-07T22:51:38.951+0000] {logging_mixin.py:149} WARNING - /home/airflow/.local/lib/python3.7/site-packages/tensorflow_io/python/ops/__init__.py:98 UserWarning: unable to load libtensorflow_io_plugins.so: unable to open file: libtensorflow_io_plugins.so, from paths: ['/home/airflow/.local/lib/python3.7/site-packages/tensorflow_io/python/ops/libtensorflow_io_plugins.so']
caused by: ["[Errno 2] The file to load file system plugin from does not exist.: '/home/airflow/.local/lib/python3.7/site-packages/tensorflow_io/python/ops/libtensorflow_io_plugins.so'"]
[2023-05-07T22:51:38.955+0000] {logging_mixin.py:149} WARNING - /home/airflow/.local/lib/python3.7/site-packages/tensorflow_io/python/ops/__init__.py:104 UserWarning: file system plugins are not loaded: unable to open file: libtensorflow_io.so, from paths: ['/home/airflow/.local/lib/python3.7/site-packages/tensorflow_io/python/ops/libtensorflow_io.so']
caused by: ['/home/airflow/.local/lib/python3.7/site-packages/tensorflow_io/python/ops/libtensorflow_io.so: cannot open shared object file: No such file or directory']
[2023-05-07T22:51:39.133+0000] {processor.py:811} WARNING - No viable dags retrieved from /opt/airflow/dags/utils/fetching_best_model.py
[2023-05-07T22:51:39.146+0000] {processor.py:178} INFO - Processing /opt/airflow/dags/utils/fetching_best_model.py took 4.123 seconds
[2023-05-07T22:52:09.382+0000] {processor.py:156} INFO - Started process (PID=199) to work on /opt/airflow/dags/utils/fetching_best_model.py
[2023-05-07T22:52:09.383+0000] {processor.py:799} INFO - Processing file /opt/airflow/dags/utils/fetching_best_model.py for tasks to queue
[2023-05-07T22:52:09.384+0000] {logging_mixin.py:149} INFO - [2023-05-07T22:52:09.384+0000] {dagbag.py:541} INFO - Filling up the DagBag from /opt/airflow/dags/utils/fetching_best_model.py
[2023-05-07T22:52:11.138+0000] {logging_mixin.py:149} WARNING - /home/airflow/.local/lib/python3.7/site-packages/tensorflow_io/python/ops/__init__.py:98 UserWarning: unable to load libtensorflow_io_plugins.so: unable to open file: libtensorflow_io_plugins.so, from paths: ['/home/airflow/.local/lib/python3.7/site-packages/tensorflow_io/python/ops/libtensorflow_io_plugins.so']
caused by: ["[Errno 2] The file to load file system plugin from does not exist.: '/home/airflow/.local/lib/python3.7/site-packages/tensorflow_io/python/ops/libtensorflow_io_plugins.so'"]
[2023-05-07T22:52:11.140+0000] {logging_mixin.py:149} WARNING - /home/airflow/.local/lib/python3.7/site-packages/tensorflow_io/python/ops/__init__.py:104 UserWarning: file system plugins are not loaded: unable to open file: libtensorflow_io.so, from paths: ['/home/airflow/.local/lib/python3.7/site-packages/tensorflow_io/python/ops/libtensorflow_io.so']
caused by: ['/home/airflow/.local/lib/python3.7/site-packages/tensorflow_io/python/ops/libtensorflow_io.so: cannot open shared object file: No such file or directory']
[2023-05-07T22:52:11.253+0000] {processor.py:811} WARNING - No viable dags retrieved from /opt/airflow/dags/utils/fetching_best_model.py
[2023-05-07T22:52:11.265+0000] {processor.py:178} INFO - Processing /opt/airflow/dags/utils/fetching_best_model.py took 1.886 seconds
[2023-05-07T22:52:42.233+0000] {processor.py:156} INFO - Started process (PID=260) to work on /opt/airflow/dags/utils/fetching_best_model.py
[2023-05-07T22:52:42.236+0000] {processor.py:799} INFO - Processing file /opt/airflow/dags/utils/fetching_best_model.py for tasks to queue
[2023-05-07T22:52:42.237+0000] {logging_mixin.py:149} INFO - [2023-05-07T22:52:42.237+0000] {dagbag.py:541} INFO - Filling up the DagBag from /opt/airflow/dags/utils/fetching_best_model.py
[2023-05-07T22:52:43.940+0000] {logging_mixin.py:149} WARNING - /home/airflow/.local/lib/python3.7/site-packages/tensorflow_io/python/ops/__init__.py:98 UserWarning: unable to load libtensorflow_io_plugins.so: unable to open file: libtensorflow_io_plugins.so, from paths: ['/home/airflow/.local/lib/python3.7/site-packages/tensorflow_io/python/ops/libtensorflow_io_plugins.so']
caused by: ["[Errno 2] The file to load file system plugin from does not exist.: '/home/airflow/.local/lib/python3.7/site-packages/tensorflow_io/python/ops/libtensorflow_io_plugins.so'"]
[2023-05-07T22:52:43.943+0000] {logging_mixin.py:149} WARNING - /home/airflow/.local/lib/python3.7/site-packages/tensorflow_io/python/ops/__init__.py:104 UserWarning: file system plugins are not loaded: unable to open file: libtensorflow_io.so, from paths: ['/home/airflow/.local/lib/python3.7/site-packages/tensorflow_io/python/ops/libtensorflow_io.so']
caused by: ['/home/airflow/.local/lib/python3.7/site-packages/tensorflow_io/python/ops/libtensorflow_io.so: cannot open shared object file: No such file or directory']
[2023-05-07T22:52:44.041+0000] {processor.py:811} WARNING - No viable dags retrieved from /opt/airflow/dags/utils/fetching_best_model.py
[2023-05-07T22:52:44.073+0000] {processor.py:178} INFO - Processing /opt/airflow/dags/utils/fetching_best_model.py took 1.845 seconds
[2023-05-07T22:53:14.630+0000] {processor.py:156} INFO - Started process (PID=329) to work on /opt/airflow/dags/utils/fetching_best_model.py
[2023-05-07T22:53:14.635+0000] {processor.py:799} INFO - Processing file /opt/airflow/dags/utils/fetching_best_model.py for tasks to queue
[2023-05-07T22:53:14.639+0000] {logging_mixin.py:149} INFO - [2023-05-07T22:53:14.639+0000] {dagbag.py:541} INFO - Filling up the DagBag from /opt/airflow/dags/utils/fetching_best_model.py
[2023-05-07T22:53:16.471+0000] {logging_mixin.py:149} WARNING - /home/airflow/.local/lib/python3.7/site-packages/tensorflow_io/python/ops/__init__.py:98 UserWarning: unable to load libtensorflow_io_plugins.so: unable to open file: libtensorflow_io_plugins.so, from paths: ['/home/airflow/.local/lib/python3.7/site-packages/tensorflow_io/python/ops/libtensorflow_io_plugins.so']
caused by: ["[Errno 2] The file to load file system plugin from does not exist.: '/home/airflow/.local/lib/python3.7/site-packages/tensorflow_io/python/ops/libtensorflow_io_plugins.so'"]
[2023-05-07T22:53:16.474+0000] {logging_mixin.py:149} WARNING - /home/airflow/.local/lib/python3.7/site-packages/tensorflow_io/python/ops/__init__.py:104 UserWarning: file system plugins are not loaded: unable to open file: libtensorflow_io.so, from paths: ['/home/airflow/.local/lib/python3.7/site-packages/tensorflow_io/python/ops/libtensorflow_io.so']
caused by: ['/home/airflow/.local/lib/python3.7/site-packages/tensorflow_io/python/ops/libtensorflow_io.so: cannot open shared object file: No such file or directory']
[2023-05-07T22:53:16.586+0000] {processor.py:811} WARNING - No viable dags retrieved from /opt/airflow/dags/utils/fetching_best_model.py
[2023-05-07T22:53:16.600+0000] {processor.py:178} INFO - Processing /opt/airflow/dags/utils/fetching_best_model.py took 1.979 seconds
[2023-05-07T22:53:46.726+0000] {processor.py:156} INFO - Started process (PID=390) to work on /opt/airflow/dags/utils/fetching_best_model.py
[2023-05-07T22:53:46.728+0000] {processor.py:799} INFO - Processing file /opt/airflow/dags/utils/fetching_best_model.py for tasks to queue
[2023-05-07T22:53:46.729+0000] {logging_mixin.py:149} INFO - [2023-05-07T22:53:46.729+0000] {dagbag.py:541} INFO - Filling up the DagBag from /opt/airflow/dags/utils/fetching_best_model.py
[2023-05-07T22:53:48.157+0000] {logging_mixin.py:149} WARNING - /home/airflow/.local/lib/python3.7/site-packages/tensorflow_io/python/ops/__init__.py:98 UserWarning: unable to load libtensorflow_io_plugins.so: unable to open file: libtensorflow_io_plugins.so, from paths: ['/home/airflow/.local/lib/python3.7/site-packages/tensorflow_io/python/ops/libtensorflow_io_plugins.so']
caused by: ["[Errno 2] The file to load file system plugin from does not exist.: '/home/airflow/.local/lib/python3.7/site-packages/tensorflow_io/python/ops/libtensorflow_io_plugins.so'"]
[2023-05-07T22:53:48.159+0000] {logging_mixin.py:149} WARNING - /home/airflow/.local/lib/python3.7/site-packages/tensorflow_io/python/ops/__init__.py:104 UserWarning: file system plugins are not loaded: unable to open file: libtensorflow_io.so, from paths: ['/home/airflow/.local/lib/python3.7/site-packages/tensorflow_io/python/ops/libtensorflow_io.so']
caused by: ['/home/airflow/.local/lib/python3.7/site-packages/tensorflow_io/python/ops/libtensorflow_io.so: cannot open shared object file: No such file or directory']
[2023-05-07T22:53:48.234+0000] {processor.py:811} WARNING - No viable dags retrieved from /opt/airflow/dags/utils/fetching_best_model.py
[2023-05-07T22:53:48.243+0000] {processor.py:178} INFO - Processing /opt/airflow/dags/utils/fetching_best_model.py took 1.523 seconds
[2023-05-07T22:54:18.549+0000] {processor.py:156} INFO - Started process (PID=460) to work on /opt/airflow/dags/utils/fetching_best_model.py
[2023-05-07T22:54:18.551+0000] {processor.py:799} INFO - Processing file /opt/airflow/dags/utils/fetching_best_model.py for tasks to queue
[2023-05-07T22:54:18.551+0000] {logging_mixin.py:149} INFO - [2023-05-07T22:54:18.551+0000] {dagbag.py:541} INFO - Filling up the DagBag from /opt/airflow/dags/utils/fetching_best_model.py
[2023-05-07T22:54:19.914+0000] {logging_mixin.py:149} WARNING - /home/airflow/.local/lib/python3.7/site-packages/tensorflow_io/python/ops/__init__.py:98 UserWarning: unable to load libtensorflow_io_plugins.so: unable to open file: libtensorflow_io_plugins.so, from paths: ['/home/airflow/.local/lib/python3.7/site-packages/tensorflow_io/python/ops/libtensorflow_io_plugins.so']
caused by: ["[Errno 2] The file to load file system plugin from does not exist.: '/home/airflow/.local/lib/python3.7/site-packages/tensorflow_io/python/ops/libtensorflow_io_plugins.so'"]
[2023-05-07T22:54:19.916+0000] {logging_mixin.py:149} WARNING - /home/airflow/.local/lib/python3.7/site-packages/tensorflow_io/python/ops/__init__.py:104 UserWarning: file system plugins are not loaded: unable to open file: libtensorflow_io.so, from paths: ['/home/airflow/.local/lib/python3.7/site-packages/tensorflow_io/python/ops/libtensorflow_io.so']
caused by: ['/home/airflow/.local/lib/python3.7/site-packages/tensorflow_io/python/ops/libtensorflow_io.so: cannot open shared object file: No such file or directory']
[2023-05-07T22:54:19.990+0000] {processor.py:811} WARNING - No viable dags retrieved from /opt/airflow/dags/utils/fetching_best_model.py
[2023-05-07T22:54:20.001+0000] {processor.py:178} INFO - Processing /opt/airflow/dags/utils/fetching_best_model.py took 1.455 seconds
[2023-05-07T22:54:50.113+0000] {processor.py:156} INFO - Started process (PID=521) to work on /opt/airflow/dags/utils/fetching_best_model.py
[2023-05-07T22:54:50.116+0000] {processor.py:799} INFO - Processing file /opt/airflow/dags/utils/fetching_best_model.py for tasks to queue
[2023-05-07T22:54:50.118+0000] {logging_mixin.py:149} INFO - [2023-05-07T22:54:50.117+0000] {dagbag.py:541} INFO - Filling up the DagBag from /opt/airflow/dags/utils/fetching_best_model.py
[2023-05-07T22:54:51.411+0000] {logging_mixin.py:149} WARNING - /home/airflow/.local/lib/python3.7/site-packages/tensorflow_io/python/ops/__init__.py:98 UserWarning: unable to load libtensorflow_io_plugins.so: unable to open file: libtensorflow_io_plugins.so, from paths: ['/home/airflow/.local/lib/python3.7/site-packages/tensorflow_io/python/ops/libtensorflow_io_plugins.so']
caused by: ["[Errno 2] The file to load file system plugin from does not exist.: '/home/airflow/.local/lib/python3.7/site-packages/tensorflow_io/python/ops/libtensorflow_io_plugins.so'"]
[2023-05-07T22:54:51.414+0000] {logging_mixin.py:149} WARNING - /home/airflow/.local/lib/python3.7/site-packages/tensorflow_io/python/ops/__init__.py:104 UserWarning: file system plugins are not loaded: unable to open file: libtensorflow_io.so, from paths: ['/home/airflow/.local/lib/python3.7/site-packages/tensorflow_io/python/ops/libtensorflow_io.so']
caused by: ['/home/airflow/.local/lib/python3.7/site-packages/tensorflow_io/python/ops/libtensorflow_io.so: cannot open shared object file: No such file or directory']
[2023-05-07T22:54:51.518+0000] {processor.py:811} WARNING - No viable dags retrieved from /opt/airflow/dags/utils/fetching_best_model.py
[2023-05-07T22:54:51.528+0000] {processor.py:178} INFO - Processing /opt/airflow/dags/utils/fetching_best_model.py took 1.421 seconds
[2023-05-07T22:55:21.943+0000] {processor.py:156} INFO - Started process (PID=582) to work on /opt/airflow/dags/utils/fetching_best_model.py
[2023-05-07T22:55:21.946+0000] {processor.py:799} INFO - Processing file /opt/airflow/dags/utils/fetching_best_model.py for tasks to queue
[2023-05-07T22:55:21.947+0000] {logging_mixin.py:149} INFO - [2023-05-07T22:55:21.947+0000] {dagbag.py:541} INFO - Filling up the DagBag from /opt/airflow/dags/utils/fetching_best_model.py
[2023-05-07T22:55:23.319+0000] {logging_mixin.py:149} WARNING - /home/airflow/.local/lib/python3.7/site-packages/tensorflow_io/python/ops/__init__.py:98 UserWarning: unable to load libtensorflow_io_plugins.so: unable to open file: libtensorflow_io_plugins.so, from paths: ['/home/airflow/.local/lib/python3.7/site-packages/tensorflow_io/python/ops/libtensorflow_io_plugins.so']
caused by: ["[Errno 2] The file to load file system plugin from does not exist.: '/home/airflow/.local/lib/python3.7/site-packages/tensorflow_io/python/ops/libtensorflow_io_plugins.so'"]
[2023-05-07T22:55:23.322+0000] {logging_mixin.py:149} WARNING - /home/airflow/.local/lib/python3.7/site-packages/tensorflow_io/python/ops/__init__.py:104 UserWarning: file system plugins are not loaded: unable to open file: libtensorflow_io.so, from paths: ['/home/airflow/.local/lib/python3.7/site-packages/tensorflow_io/python/ops/libtensorflow_io.so']
caused by: ['/home/airflow/.local/lib/python3.7/site-packages/tensorflow_io/python/ops/libtensorflow_io.so: cannot open shared object file: No such file or directory']
[2023-05-07T22:55:23.417+0000] {processor.py:811} WARNING - No viable dags retrieved from /opt/airflow/dags/utils/fetching_best_model.py
[2023-05-07T22:55:23.439+0000] {processor.py:178} INFO - Processing /opt/airflow/dags/utils/fetching_best_model.py took 1.502 seconds
[2023-05-07T22:55:53.587+0000] {processor.py:156} INFO - Started process (PID=643) to work on /opt/airflow/dags/utils/fetching_best_model.py
[2023-05-07T22:55:53.590+0000] {processor.py:799} INFO - Processing file /opt/airflow/dags/utils/fetching_best_model.py for tasks to queue
[2023-05-07T22:55:53.592+0000] {logging_mixin.py:149} INFO - [2023-05-07T22:55:53.592+0000] {dagbag.py:541} INFO - Filling up the DagBag from /opt/airflow/dags/utils/fetching_best_model.py
[2023-05-07T22:55:55.032+0000] {logging_mixin.py:149} WARNING - /home/airflow/.local/lib/python3.7/site-packages/tensorflow_io/python/ops/__init__.py:98 UserWarning: unable to load libtensorflow_io_plugins.so: unable to open file: libtensorflow_io_plugins.so, from paths: ['/home/airflow/.local/lib/python3.7/site-packages/tensorflow_io/python/ops/libtensorflow_io_plugins.so']
caused by: ["[Errno 2] The file to load file system plugin from does not exist.: '/home/airflow/.local/lib/python3.7/site-packages/tensorflow_io/python/ops/libtensorflow_io_plugins.so'"]
[2023-05-07T22:55:55.035+0000] {logging_mixin.py:149} WARNING - /home/airflow/.local/lib/python3.7/site-packages/tensorflow_io/python/ops/__init__.py:104 UserWarning: file system plugins are not loaded: unable to open file: libtensorflow_io.so, from paths: ['/home/airflow/.local/lib/python3.7/site-packages/tensorflow_io/python/ops/libtensorflow_io.so']
caused by: ['/home/airflow/.local/lib/python3.7/site-packages/tensorflow_io/python/ops/libtensorflow_io.so: cannot open shared object file: No such file or directory']
[2023-05-07T22:55:55.121+0000] {processor.py:811} WARNING - No viable dags retrieved from /opt/airflow/dags/utils/fetching_best_model.py
[2023-05-07T22:55:55.132+0000] {processor.py:178} INFO - Processing /opt/airflow/dags/utils/fetching_best_model.py took 1.551 seconds
[2023-05-07T22:56:25.627+0000] {processor.py:156} INFO - Started process (PID=704) to work on /opt/airflow/dags/utils/fetching_best_model.py
[2023-05-07T22:56:25.631+0000] {processor.py:799} INFO - Processing file /opt/airflow/dags/utils/fetching_best_model.py for tasks to queue
[2023-05-07T22:56:25.632+0000] {logging_mixin.py:149} INFO - [2023-05-07T22:56:25.632+0000] {dagbag.py:541} INFO - Filling up the DagBag from /opt/airflow/dags/utils/fetching_best_model.py
[2023-05-07T22:56:26.984+0000] {logging_mixin.py:149} WARNING - /home/airflow/.local/lib/python3.7/site-packages/tensorflow_io/python/ops/__init__.py:98 UserWarning: unable to load libtensorflow_io_plugins.so: unable to open file: libtensorflow_io_plugins.so, from paths: ['/home/airflow/.local/lib/python3.7/site-packages/tensorflow_io/python/ops/libtensorflow_io_plugins.so']
caused by: ["[Errno 2] The file to load file system plugin from does not exist.: '/home/airflow/.local/lib/python3.7/site-packages/tensorflow_io/python/ops/libtensorflow_io_plugins.so'"]
[2023-05-07T22:56:26.987+0000] {logging_mixin.py:149} WARNING - /home/airflow/.local/lib/python3.7/site-packages/tensorflow_io/python/ops/__init__.py:104 UserWarning: file system plugins are not loaded: unable to open file: libtensorflow_io.so, from paths: ['/home/airflow/.local/lib/python3.7/site-packages/tensorflow_io/python/ops/libtensorflow_io.so']
caused by: ['/home/airflow/.local/lib/python3.7/site-packages/tensorflow_io/python/ops/libtensorflow_io.so: cannot open shared object file: No such file or directory']
[2023-05-07T22:56:27.075+0000] {processor.py:811} WARNING - No viable dags retrieved from /opt/airflow/dags/utils/fetching_best_model.py
[2023-05-07T22:56:27.088+0000] {processor.py:178} INFO - Processing /opt/airflow/dags/utils/fetching_best_model.py took 1.467 seconds
[2023-05-07T22:56:57.683+0000] {processor.py:156} INFO - Started process (PID=771) to work on /opt/airflow/dags/utils/fetching_best_model.py
[2023-05-07T22:56:57.686+0000] {processor.py:799} INFO - Processing file /opt/airflow/dags/utils/fetching_best_model.py for tasks to queue
[2023-05-07T22:56:57.689+0000] {logging_mixin.py:149} INFO - [2023-05-07T22:56:57.688+0000] {dagbag.py:541} INFO - Filling up the DagBag from /opt/airflow/dags/utils/fetching_best_model.py
[2023-05-07T22:56:59.040+0000] {logging_mixin.py:149} WARNING - /home/airflow/.local/lib/python3.7/site-packages/tensorflow_io/python/ops/__init__.py:98 UserWarning: unable to load libtensorflow_io_plugins.so: unable to open file: libtensorflow_io_plugins.so, from paths: ['/home/airflow/.local/lib/python3.7/site-packages/tensorflow_io/python/ops/libtensorflow_io_plugins.so']
caused by: ["[Errno 2] The file to load file system plugin from does not exist.: '/home/airflow/.local/lib/python3.7/site-packages/tensorflow_io/python/ops/libtensorflow_io_plugins.so'"]
[2023-05-07T22:56:59.042+0000] {logging_mixin.py:149} WARNING - /home/airflow/.local/lib/python3.7/site-packages/tensorflow_io/python/ops/__init__.py:104 UserWarning: file system plugins are not loaded: unable to open file: libtensorflow_io.so, from paths: ['/home/airflow/.local/lib/python3.7/site-packages/tensorflow_io/python/ops/libtensorflow_io.so']
caused by: ['/home/airflow/.local/lib/python3.7/site-packages/tensorflow_io/python/ops/libtensorflow_io.so: cannot open shared object file: No such file or directory']
[2023-05-07T22:56:59.118+0000] {processor.py:811} WARNING - No viable dags retrieved from /opt/airflow/dags/utils/fetching_best_model.py
[2023-05-07T22:56:59.128+0000] {processor.py:178} INFO - Processing /opt/airflow/dags/utils/fetching_best_model.py took 1.451 seconds
[2023-05-07T22:57:29.250+0000] {processor.py:156} INFO - Started process (PID=832) to work on /opt/airflow/dags/utils/fetching_best_model.py
[2023-05-07T22:57:29.253+0000] {processor.py:799} INFO - Processing file /opt/airflow/dags/utils/fetching_best_model.py for tasks to queue
[2023-05-07T22:57:29.254+0000] {logging_mixin.py:149} INFO - [2023-05-07T22:57:29.254+0000] {dagbag.py:541} INFO - Filling up the DagBag from /opt/airflow/dags/utils/fetching_best_model.py
[2023-05-07T22:57:30.755+0000] {logging_mixin.py:149} WARNING - /home/airflow/.local/lib/python3.7/site-packages/tensorflow_io/python/ops/__init__.py:98 UserWarning: unable to load libtensorflow_io_plugins.so: unable to open file: libtensorflow_io_plugins.so, from paths: ['/home/airflow/.local/lib/python3.7/site-packages/tensorflow_io/python/ops/libtensorflow_io_plugins.so']
caused by: ["[Errno 2] The file to load file system plugin from does not exist.: '/home/airflow/.local/lib/python3.7/site-packages/tensorflow_io/python/ops/libtensorflow_io_plugins.so'"]
[2023-05-07T22:57:30.757+0000] {logging_mixin.py:149} WARNING - /home/airflow/.local/lib/python3.7/site-packages/tensorflow_io/python/ops/__init__.py:104 UserWarning: file system plugins are not loaded: unable to open file: libtensorflow_io.so, from paths: ['/home/airflow/.local/lib/python3.7/site-packages/tensorflow_io/python/ops/libtensorflow_io.so']
caused by: ['/home/airflow/.local/lib/python3.7/site-packages/tensorflow_io/python/ops/libtensorflow_io.so: cannot open shared object file: No such file or directory']
[2023-05-07T22:57:30.846+0000] {processor.py:811} WARNING - No viable dags retrieved from /opt/airflow/dags/utils/fetching_best_model.py
[2023-05-07T22:57:30.859+0000] {processor.py:178} INFO - Processing /opt/airflow/dags/utils/fetching_best_model.py took 1.617 seconds
[2023-05-07T22:58:01.228+0000] {processor.py:156} INFO - Started process (PID=893) to work on /opt/airflow/dags/utils/fetching_best_model.py
[2023-05-07T22:58:01.230+0000] {processor.py:799} INFO - Processing file /opt/airflow/dags/utils/fetching_best_model.py for tasks to queue
[2023-05-07T22:58:01.232+0000] {logging_mixin.py:149} INFO - [2023-05-07T22:58:01.232+0000] {dagbag.py:541} INFO - Filling up the DagBag from /opt/airflow/dags/utils/fetching_best_model.py
[2023-05-07T22:58:02.512+0000] {logging_mixin.py:149} WARNING - /home/airflow/.local/lib/python3.7/site-packages/tensorflow_io/python/ops/__init__.py:98 UserWarning: unable to load libtensorflow_io_plugins.so: unable to open file: libtensorflow_io_plugins.so, from paths: ['/home/airflow/.local/lib/python3.7/site-packages/tensorflow_io/python/ops/libtensorflow_io_plugins.so']
caused by: ["[Errno 2] The file to load file system plugin from does not exist.: '/home/airflow/.local/lib/python3.7/site-packages/tensorflow_io/python/ops/libtensorflow_io_plugins.so'"]
[2023-05-07T22:58:02.514+0000] {logging_mixin.py:149} WARNING - /home/airflow/.local/lib/python3.7/site-packages/tensorflow_io/python/ops/__init__.py:104 UserWarning: file system plugins are not loaded: unable to open file: libtensorflow_io.so, from paths: ['/home/airflow/.local/lib/python3.7/site-packages/tensorflow_io/python/ops/libtensorflow_io.so']
caused by: ['/home/airflow/.local/lib/python3.7/site-packages/tensorflow_io/python/ops/libtensorflow_io.so: cannot open shared object file: No such file or directory']
[2023-05-07T22:58:02.592+0000] {processor.py:811} WARNING - No viable dags retrieved from /opt/airflow/dags/utils/fetching_best_model.py
[2023-05-07T22:58:02.602+0000] {processor.py:178} INFO - Processing /opt/airflow/dags/utils/fetching_best_model.py took 1.380 seconds
[2023-05-07T22:58:32.969+0000] {processor.py:156} INFO - Started process (PID=954) to work on /opt/airflow/dags/utils/fetching_best_model.py
[2023-05-07T22:58:32.973+0000] {processor.py:799} INFO - Processing file /opt/airflow/dags/utils/fetching_best_model.py for tasks to queue
[2023-05-07T22:58:32.975+0000] {logging_mixin.py:149} INFO - [2023-05-07T22:58:32.975+0000] {dagbag.py:541} INFO - Filling up the DagBag from /opt/airflow/dags/utils/fetching_best_model.py
[2023-05-07T22:58:34.402+0000] {logging_mixin.py:149} WARNING - /home/airflow/.local/lib/python3.7/site-packages/tensorflow_io/python/ops/__init__.py:98 UserWarning: unable to load libtensorflow_io_plugins.so: unable to open file: libtensorflow_io_plugins.so, from paths: ['/home/airflow/.local/lib/python3.7/site-packages/tensorflow_io/python/ops/libtensorflow_io_plugins.so']
caused by: ["[Errno 2] The file to load file system plugin from does not exist.: '/home/airflow/.local/lib/python3.7/site-packages/tensorflow_io/python/ops/libtensorflow_io_plugins.so'"]
[2023-05-07T22:58:34.404+0000] {logging_mixin.py:149} WARNING - /home/airflow/.local/lib/python3.7/site-packages/tensorflow_io/python/ops/__init__.py:104 UserWarning: file system plugins are not loaded: unable to open file: libtensorflow_io.so, from paths: ['/home/airflow/.local/lib/python3.7/site-packages/tensorflow_io/python/ops/libtensorflow_io.so']
caused by: ['/home/airflow/.local/lib/python3.7/site-packages/tensorflow_io/python/ops/libtensorflow_io.so: cannot open shared object file: No such file or directory']
[2023-05-07T22:58:34.481+0000] {processor.py:811} WARNING - No viable dags retrieved from /opt/airflow/dags/utils/fetching_best_model.py
[2023-05-07T22:58:34.492+0000] {processor.py:178} INFO - Processing /opt/airflow/dags/utils/fetching_best_model.py took 1.529 seconds
[2023-05-07T22:59:04.807+0000] {processor.py:156} INFO - Started process (PID=1015) to work on /opt/airflow/dags/utils/fetching_best_model.py
[2023-05-07T22:59:04.809+0000] {processor.py:799} INFO - Processing file /opt/airflow/dags/utils/fetching_best_model.py for tasks to queue
[2023-05-07T22:59:04.811+0000] {logging_mixin.py:149} INFO - [2023-05-07T22:59:04.811+0000] {dagbag.py:541} INFO - Filling up the DagBag from /opt/airflow/dags/utils/fetching_best_model.py
[2023-05-07T22:59:06.193+0000] {logging_mixin.py:149} WARNING - /home/airflow/.local/lib/python3.7/site-packages/tensorflow_io/python/ops/__init__.py:98 UserWarning: unable to load libtensorflow_io_plugins.so: unable to open file: libtensorflow_io_plugins.so, from paths: ['/home/airflow/.local/lib/python3.7/site-packages/tensorflow_io/python/ops/libtensorflow_io_plugins.so']
caused by: ["[Errno 2] The file to load file system plugin from does not exist.: '/home/airflow/.local/lib/python3.7/site-packages/tensorflow_io/python/ops/libtensorflow_io_plugins.so'"]
[2023-05-07T22:59:06.195+0000] {logging_mixin.py:149} WARNING - /home/airflow/.local/lib/python3.7/site-packages/tensorflow_io/python/ops/__init__.py:104 UserWarning: file system plugins are not loaded: unable to open file: libtensorflow_io.so, from paths: ['/home/airflow/.local/lib/python3.7/site-packages/tensorflow_io/python/ops/libtensorflow_io.so']
caused by: ['/home/airflow/.local/lib/python3.7/site-packages/tensorflow_io/python/ops/libtensorflow_io.so: cannot open shared object file: No such file or directory']
[2023-05-07T22:59:06.280+0000] {processor.py:811} WARNING - No viable dags retrieved from /opt/airflow/dags/utils/fetching_best_model.py
[2023-05-07T22:59:06.290+0000] {processor.py:178} INFO - Processing /opt/airflow/dags/utils/fetching_best_model.py took 1.491 seconds
[2023-05-07T22:59:36.662+0000] {processor.py:156} INFO - Started process (PID=1076) to work on /opt/airflow/dags/utils/fetching_best_model.py
[2023-05-07T22:59:36.665+0000] {processor.py:799} INFO - Processing file /opt/airflow/dags/utils/fetching_best_model.py for tasks to queue
[2023-05-07T22:59:36.667+0000] {logging_mixin.py:149} INFO - [2023-05-07T22:59:36.666+0000] {dagbag.py:541} INFO - Filling up the DagBag from /opt/airflow/dags/utils/fetching_best_model.py
[2023-05-07T22:59:38.043+0000] {logging_mixin.py:149} WARNING - /home/airflow/.local/lib/python3.7/site-packages/tensorflow_io/python/ops/__init__.py:98 UserWarning: unable to load libtensorflow_io_plugins.so: unable to open file: libtensorflow_io_plugins.so, from paths: ['/home/airflow/.local/lib/python3.7/site-packages/tensorflow_io/python/ops/libtensorflow_io_plugins.so']
caused by: ["[Errno 2] The file to load file system plugin from does not exist.: '/home/airflow/.local/lib/python3.7/site-packages/tensorflow_io/python/ops/libtensorflow_io_plugins.so'"]
[2023-05-07T22:59:38.045+0000] {logging_mixin.py:149} WARNING - /home/airflow/.local/lib/python3.7/site-packages/tensorflow_io/python/ops/__init__.py:104 UserWarning: file system plugins are not loaded: unable to open file: libtensorflow_io.so, from paths: ['/home/airflow/.local/lib/python3.7/site-packages/tensorflow_io/python/ops/libtensorflow_io.so']
caused by: ['/home/airflow/.local/lib/python3.7/site-packages/tensorflow_io/python/ops/libtensorflow_io.so: cannot open shared object file: No such file or directory']
[2023-05-07T22:59:38.129+0000] {processor.py:811} WARNING - No viable dags retrieved from /opt/airflow/dags/utils/fetching_best_model.py
[2023-05-07T22:59:38.141+0000] {processor.py:178} INFO - Processing /opt/airflow/dags/utils/fetching_best_model.py took 1.484 seconds
[2023-05-07T23:04:00.982+0000] {processor.py:156} INFO - Started process (PID=50) to work on /opt/airflow/dags/utils/fetching_best_model.py
[2023-05-07T23:04:00.984+0000] {processor.py:799} INFO - Processing file /opt/airflow/dags/utils/fetching_best_model.py for tasks to queue
[2023-05-07T23:04:00.985+0000] {logging_mixin.py:149} INFO - [2023-05-07T23:04:00.985+0000] {dagbag.py:541} INFO - Filling up the DagBag from /opt/airflow/dags/utils/fetching_best_model.py
[2023-05-07T23:04:00.994+0000] {logging_mixin.py:149} INFO - [2023-05-07T23:04:00.992+0000] {dagbag.py:350} ERROR - Failed to import: /opt/airflow/dags/utils/fetching_best_model.py
Traceback (most recent call last):
  File "/home/airflow/.local/lib/python3.7/site-packages/airflow/models/dagbag.py", line 346, in parse
    loader.exec_module(new_module)
  File "<frozen importlib._bootstrap_external>", line 728, in exec_module
  File "<frozen importlib._bootstrap>", line 219, in _call_with_frames_removed
  File "/opt/airflow/dags/utils/fetching_best_model.py", line 1, in <module>
    from sklearn.preprocessing import MinMaxScaler
ModuleNotFoundError: No module named 'sklearn'
[2023-05-07T23:04:00.996+0000] {processor.py:811} WARNING - No viable dags retrieved from /opt/airflow/dags/utils/fetching_best_model.py
[2023-05-07T23:04:01.057+0000] {processor.py:178} INFO - Processing /opt/airflow/dags/utils/fetching_best_model.py took 0.078 seconds
[2023-05-07T23:04:31.487+0000] {processor.py:156} INFO - Started process (PID=103) to work on /opt/airflow/dags/utils/fetching_best_model.py
[2023-05-07T23:04:31.489+0000] {processor.py:799} INFO - Processing file /opt/airflow/dags/utils/fetching_best_model.py for tasks to queue
[2023-05-07T23:04:31.489+0000] {logging_mixin.py:149} INFO - [2023-05-07T23:04:31.489+0000] {dagbag.py:541} INFO - Filling up the DagBag from /opt/airflow/dags/utils/fetching_best_model.py
[2023-05-07T23:04:31.495+0000] {logging_mixin.py:149} INFO - [2023-05-07T23:04:31.493+0000] {dagbag.py:350} ERROR - Failed to import: /opt/airflow/dags/utils/fetching_best_model.py
Traceback (most recent call last):
  File "/home/airflow/.local/lib/python3.7/site-packages/airflow/models/dagbag.py", line 346, in parse
    loader.exec_module(new_module)
  File "<frozen importlib._bootstrap_external>", line 728, in exec_module
  File "<frozen importlib._bootstrap>", line 219, in _call_with_frames_removed
  File "/opt/airflow/dags/utils/fetching_best_model.py", line 1, in <module>
    from sklearn.preprocessing import MinMaxScaler
ModuleNotFoundError: No module named 'sklearn'
[2023-05-07T23:04:31.495+0000] {processor.py:811} WARNING - No viable dags retrieved from /opt/airflow/dags/utils/fetching_best_model.py
[2023-05-07T23:04:31.514+0000] {processor.py:178} INFO - Processing /opt/airflow/dags/utils/fetching_best_model.py took 0.031 seconds
[2023-05-07T23:05:01.918+0000] {processor.py:156} INFO - Started process (PID=156) to work on /opt/airflow/dags/utils/fetching_best_model.py
[2023-05-07T23:05:01.920+0000] {processor.py:799} INFO - Processing file /opt/airflow/dags/utils/fetching_best_model.py for tasks to queue
[2023-05-07T23:05:01.921+0000] {logging_mixin.py:149} INFO - [2023-05-07T23:05:01.921+0000] {dagbag.py:541} INFO - Filling up the DagBag from /opt/airflow/dags/utils/fetching_best_model.py
[2023-05-07T23:05:01.926+0000] {logging_mixin.py:149} INFO - [2023-05-07T23:05:01.924+0000] {dagbag.py:350} ERROR - Failed to import: /opt/airflow/dags/utils/fetching_best_model.py
Traceback (most recent call last):
  File "/home/airflow/.local/lib/python3.7/site-packages/airflow/models/dagbag.py", line 346, in parse
    loader.exec_module(new_module)
  File "<frozen importlib._bootstrap_external>", line 728, in exec_module
  File "<frozen importlib._bootstrap>", line 219, in _call_with_frames_removed
  File "/opt/airflow/dags/utils/fetching_best_model.py", line 1, in <module>
    from sklearn.preprocessing import MinMaxScaler
ModuleNotFoundError: No module named 'sklearn'
[2023-05-07T23:05:01.926+0000] {processor.py:811} WARNING - No viable dags retrieved from /opt/airflow/dags/utils/fetching_best_model.py
[2023-05-07T23:05:01.943+0000] {processor.py:178} INFO - Processing /opt/airflow/dags/utils/fetching_best_model.py took 0.028 seconds
[2023-05-07T23:05:32.376+0000] {processor.py:156} INFO - Started process (PID=209) to work on /opt/airflow/dags/utils/fetching_best_model.py
[2023-05-07T23:05:32.377+0000] {processor.py:799} INFO - Processing file /opt/airflow/dags/utils/fetching_best_model.py for tasks to queue
[2023-05-07T23:05:32.378+0000] {logging_mixin.py:149} INFO - [2023-05-07T23:05:32.378+0000] {dagbag.py:541} INFO - Filling up the DagBag from /opt/airflow/dags/utils/fetching_best_model.py
[2023-05-07T23:05:32.382+0000] {logging_mixin.py:149} INFO - [2023-05-07T23:05:32.381+0000] {dagbag.py:350} ERROR - Failed to import: /opt/airflow/dags/utils/fetching_best_model.py
Traceback (most recent call last):
  File "/home/airflow/.local/lib/python3.7/site-packages/airflow/models/dagbag.py", line 346, in parse
    loader.exec_module(new_module)
  File "<frozen importlib._bootstrap_external>", line 728, in exec_module
  File "<frozen importlib._bootstrap>", line 219, in _call_with_frames_removed
  File "/opt/airflow/dags/utils/fetching_best_model.py", line 1, in <module>
    from sklearn.preprocessing import MinMaxScaler
ModuleNotFoundError: No module named 'sklearn'
[2023-05-07T23:05:32.382+0000] {processor.py:811} WARNING - No viable dags retrieved from /opt/airflow/dags/utils/fetching_best_model.py
[2023-05-07T23:05:32.398+0000] {processor.py:178} INFO - Processing /opt/airflow/dags/utils/fetching_best_model.py took 0.025 seconds
[2023-05-07T23:06:02.806+0000] {processor.py:156} INFO - Started process (PID=262) to work on /opt/airflow/dags/utils/fetching_best_model.py
[2023-05-07T23:06:02.807+0000] {processor.py:799} INFO - Processing file /opt/airflow/dags/utils/fetching_best_model.py for tasks to queue
[2023-05-07T23:06:02.808+0000] {logging_mixin.py:149} INFO - [2023-05-07T23:06:02.808+0000] {dagbag.py:541} INFO - Filling up the DagBag from /opt/airflow/dags/utils/fetching_best_model.py
[2023-05-07T23:06:02.813+0000] {logging_mixin.py:149} INFO - [2023-05-07T23:06:02.812+0000] {dagbag.py:350} ERROR - Failed to import: /opt/airflow/dags/utils/fetching_best_model.py
Traceback (most recent call last):
  File "/home/airflow/.local/lib/python3.7/site-packages/airflow/models/dagbag.py", line 346, in parse
    loader.exec_module(new_module)
  File "<frozen importlib._bootstrap_external>", line 728, in exec_module
  File "<frozen importlib._bootstrap>", line 219, in _call_with_frames_removed
  File "/opt/airflow/dags/utils/fetching_best_model.py", line 1, in <module>
    from sklearn.preprocessing import MinMaxScaler
ModuleNotFoundError: No module named 'sklearn'
[2023-05-07T23:06:02.814+0000] {processor.py:811} WARNING - No viable dags retrieved from /opt/airflow/dags/utils/fetching_best_model.py
[2023-05-07T23:06:02.831+0000] {processor.py:178} INFO - Processing /opt/airflow/dags/utils/fetching_best_model.py took 0.028 seconds
[2023-05-07T23:06:33.268+0000] {processor.py:156} INFO - Started process (PID=315) to work on /opt/airflow/dags/utils/fetching_best_model.py
[2023-05-07T23:06:33.270+0000] {processor.py:799} INFO - Processing file /opt/airflow/dags/utils/fetching_best_model.py for tasks to queue
[2023-05-07T23:06:33.270+0000] {logging_mixin.py:149} INFO - [2023-05-07T23:06:33.270+0000] {dagbag.py:541} INFO - Filling up the DagBag from /opt/airflow/dags/utils/fetching_best_model.py
[2023-05-07T23:06:33.276+0000] {logging_mixin.py:149} INFO - [2023-05-07T23:06:33.274+0000] {dagbag.py:350} ERROR - Failed to import: /opt/airflow/dags/utils/fetching_best_model.py
Traceback (most recent call last):
  File "/home/airflow/.local/lib/python3.7/site-packages/airflow/models/dagbag.py", line 346, in parse
    loader.exec_module(new_module)
  File "<frozen importlib._bootstrap_external>", line 728, in exec_module
  File "<frozen importlib._bootstrap>", line 219, in _call_with_frames_removed
  File "/opt/airflow/dags/utils/fetching_best_model.py", line 1, in <module>
    from sklearn.preprocessing import MinMaxScaler
ModuleNotFoundError: No module named 'sklearn'
[2023-05-07T23:06:33.277+0000] {processor.py:811} WARNING - No viable dags retrieved from /opt/airflow/dags/utils/fetching_best_model.py
[2023-05-07T23:06:33.294+0000] {processor.py:178} INFO - Processing /opt/airflow/dags/utils/fetching_best_model.py took 0.028 seconds
[2023-05-07T23:07:03.698+0000] {processor.py:156} INFO - Started process (PID=368) to work on /opt/airflow/dags/utils/fetching_best_model.py
[2023-05-07T23:07:03.699+0000] {processor.py:799} INFO - Processing file /opt/airflow/dags/utils/fetching_best_model.py for tasks to queue
[2023-05-07T23:07:03.700+0000] {logging_mixin.py:149} INFO - [2023-05-07T23:07:03.700+0000] {dagbag.py:541} INFO - Filling up the DagBag from /opt/airflow/dags/utils/fetching_best_model.py
[2023-05-07T23:07:03.704+0000] {logging_mixin.py:149} INFO - [2023-05-07T23:07:03.703+0000] {dagbag.py:350} ERROR - Failed to import: /opt/airflow/dags/utils/fetching_best_model.py
Traceback (most recent call last):
  File "/home/airflow/.local/lib/python3.7/site-packages/airflow/models/dagbag.py", line 346, in parse
    loader.exec_module(new_module)
  File "<frozen importlib._bootstrap_external>", line 728, in exec_module
  File "<frozen importlib._bootstrap>", line 219, in _call_with_frames_removed
  File "/opt/airflow/dags/utils/fetching_best_model.py", line 1, in <module>
    from sklearn.preprocessing import MinMaxScaler
ModuleNotFoundError: No module named 'sklearn'
[2023-05-07T23:07:03.705+0000] {processor.py:811} WARNING - No viable dags retrieved from /opt/airflow/dags/utils/fetching_best_model.py
[2023-05-07T23:07:03.721+0000] {processor.py:178} INFO - Processing /opt/airflow/dags/utils/fetching_best_model.py took 0.025 seconds
[2023-05-07T23:07:34.205+0000] {processor.py:156} INFO - Started process (PID=421) to work on /opt/airflow/dags/utils/fetching_best_model.py
[2023-05-07T23:07:34.206+0000] {processor.py:799} INFO - Processing file /opt/airflow/dags/utils/fetching_best_model.py for tasks to queue
[2023-05-07T23:07:34.207+0000] {logging_mixin.py:149} INFO - [2023-05-07T23:07:34.207+0000] {dagbag.py:541} INFO - Filling up the DagBag from /opt/airflow/dags/utils/fetching_best_model.py
[2023-05-07T23:07:34.211+0000] {logging_mixin.py:149} INFO - [2023-05-07T23:07:34.210+0000] {dagbag.py:350} ERROR - Failed to import: /opt/airflow/dags/utils/fetching_best_model.py
Traceback (most recent call last):
  File "/home/airflow/.local/lib/python3.7/site-packages/airflow/models/dagbag.py", line 346, in parse
    loader.exec_module(new_module)
  File "<frozen importlib._bootstrap_external>", line 728, in exec_module
  File "<frozen importlib._bootstrap>", line 219, in _call_with_frames_removed
  File "/opt/airflow/dags/utils/fetching_best_model.py", line 1, in <module>
    from sklearn.preprocessing import MinMaxScaler
ModuleNotFoundError: No module named 'sklearn'
[2023-05-07T23:07:34.212+0000] {processor.py:811} WARNING - No viable dags retrieved from /opt/airflow/dags/utils/fetching_best_model.py
[2023-05-07T23:07:34.229+0000] {processor.py:178} INFO - Processing /opt/airflow/dags/utils/fetching_best_model.py took 0.027 seconds
[2023-05-07T23:08:05.365+0000] {processor.py:156} INFO - Started process (PID=474) to work on /opt/airflow/dags/utils/fetching_best_model.py
[2023-05-07T23:08:05.366+0000] {processor.py:799} INFO - Processing file /opt/airflow/dags/utils/fetching_best_model.py for tasks to queue
[2023-05-07T23:08:05.367+0000] {logging_mixin.py:149} INFO - [2023-05-07T23:08:05.367+0000] {dagbag.py:541} INFO - Filling up the DagBag from /opt/airflow/dags/utils/fetching_best_model.py
[2023-05-07T23:08:05.372+0000] {logging_mixin.py:149} INFO - [2023-05-07T23:08:05.371+0000] {dagbag.py:350} ERROR - Failed to import: /opt/airflow/dags/utils/fetching_best_model.py
Traceback (most recent call last):
  File "/home/airflow/.local/lib/python3.7/site-packages/airflow/models/dagbag.py", line 346, in parse
    loader.exec_module(new_module)
  File "<frozen importlib._bootstrap_external>", line 728, in exec_module
  File "<frozen importlib._bootstrap>", line 219, in _call_with_frames_removed
  File "/opt/airflow/dags/utils/fetching_best_model.py", line 1, in <module>
    from sklearn.preprocessing import MinMaxScaler
ModuleNotFoundError: No module named 'sklearn'
[2023-05-07T23:08:05.377+0000] {processor.py:811} WARNING - No viable dags retrieved from /opt/airflow/dags/utils/fetching_best_model.py
[2023-05-07T23:08:05.394+0000] {processor.py:178} INFO - Processing /opt/airflow/dags/utils/fetching_best_model.py took 0.033 seconds
[2023-05-07T23:08:36.507+0000] {processor.py:156} INFO - Started process (PID=527) to work on /opt/airflow/dags/utils/fetching_best_model.py
[2023-05-07T23:08:36.509+0000] {processor.py:799} INFO - Processing file /opt/airflow/dags/utils/fetching_best_model.py for tasks to queue
[2023-05-07T23:08:36.510+0000] {logging_mixin.py:149} INFO - [2023-05-07T23:08:36.509+0000] {dagbag.py:541} INFO - Filling up the DagBag from /opt/airflow/dags/utils/fetching_best_model.py
[2023-05-07T23:08:36.517+0000] {logging_mixin.py:149} INFO - [2023-05-07T23:08:36.515+0000] {dagbag.py:350} ERROR - Failed to import: /opt/airflow/dags/utils/fetching_best_model.py
Traceback (most recent call last):
  File "/home/airflow/.local/lib/python3.7/site-packages/airflow/models/dagbag.py", line 346, in parse
    loader.exec_module(new_module)
  File "<frozen importlib._bootstrap_external>", line 728, in exec_module
  File "<frozen importlib._bootstrap>", line 219, in _call_with_frames_removed
  File "/opt/airflow/dags/utils/fetching_best_model.py", line 1, in <module>
    from sklearn.preprocessing import MinMaxScaler
ModuleNotFoundError: No module named 'sklearn'
[2023-05-07T23:08:36.518+0000] {processor.py:811} WARNING - No viable dags retrieved from /opt/airflow/dags/utils/fetching_best_model.py
[2023-05-07T23:08:36.549+0000] {processor.py:178} INFO - Processing /opt/airflow/dags/utils/fetching_best_model.py took 0.045 seconds
[2023-05-07T23:09:07.049+0000] {processor.py:156} INFO - Started process (PID=572) to work on /opt/airflow/dags/utils/fetching_best_model.py
[2023-05-07T23:09:07.051+0000] {processor.py:799} INFO - Processing file /opt/airflow/dags/utils/fetching_best_model.py for tasks to queue
[2023-05-07T23:09:07.053+0000] {logging_mixin.py:149} INFO - [2023-05-07T23:09:07.053+0000] {dagbag.py:541} INFO - Filling up the DagBag from /opt/airflow/dags/utils/fetching_best_model.py
[2023-05-07T23:09:07.060+0000] {logging_mixin.py:149} INFO - [2023-05-07T23:09:07.059+0000] {dagbag.py:350} ERROR - Failed to import: /opt/airflow/dags/utils/fetching_best_model.py
Traceback (most recent call last):
  File "/home/airflow/.local/lib/python3.7/site-packages/airflow/models/dagbag.py", line 346, in parse
    loader.exec_module(new_module)
  File "<frozen importlib._bootstrap_external>", line 728, in exec_module
  File "<frozen importlib._bootstrap>", line 219, in _call_with_frames_removed
  File "/opt/airflow/dags/utils/fetching_best_model.py", line 1, in <module>
    from sklearn.preprocessing import MinMaxScaler
ModuleNotFoundError: No module named 'sklearn'
[2023-05-07T23:09:07.061+0000] {processor.py:811} WARNING - No viable dags retrieved from /opt/airflow/dags/utils/fetching_best_model.py
[2023-05-07T23:09:07.108+0000] {processor.py:178} INFO - Processing /opt/airflow/dags/utils/fetching_best_model.py took 0.064 seconds
[2023-05-07T23:09:37.242+0000] {processor.py:156} INFO - Started process (PID=623) to work on /opt/airflow/dags/utils/fetching_best_model.py
[2023-05-07T23:09:37.244+0000] {processor.py:799} INFO - Processing file /opt/airflow/dags/utils/fetching_best_model.py for tasks to queue
[2023-05-07T23:09:37.246+0000] {logging_mixin.py:149} INFO - [2023-05-07T23:09:37.246+0000] {dagbag.py:541} INFO - Filling up the DagBag from /opt/airflow/dags/utils/fetching_best_model.py
[2023-05-07T23:09:37.252+0000] {logging_mixin.py:149} INFO - [2023-05-07T23:09:37.250+0000] {dagbag.py:350} ERROR - Failed to import: /opt/airflow/dags/utils/fetching_best_model.py
Traceback (most recent call last):
  File "/home/airflow/.local/lib/python3.7/site-packages/airflow/models/dagbag.py", line 346, in parse
    loader.exec_module(new_module)
  File "<frozen importlib._bootstrap_external>", line 728, in exec_module
  File "<frozen importlib._bootstrap>", line 219, in _call_with_frames_removed
  File "/opt/airflow/dags/utils/fetching_best_model.py", line 1, in <module>
    from sklearn.preprocessing import MinMaxScaler
ModuleNotFoundError: No module named 'sklearn'
[2023-05-07T23:09:37.252+0000] {processor.py:811} WARNING - No viable dags retrieved from /opt/airflow/dags/utils/fetching_best_model.py
[2023-05-07T23:09:37.271+0000] {processor.py:178} INFO - Processing /opt/airflow/dags/utils/fetching_best_model.py took 0.032 seconds
[2023-05-07T23:10:07.764+0000] {processor.py:156} INFO - Started process (PID=669) to work on /opt/airflow/dags/utils/fetching_best_model.py
[2023-05-07T23:10:07.765+0000] {processor.py:799} INFO - Processing file /opt/airflow/dags/utils/fetching_best_model.py for tasks to queue
[2023-05-07T23:10:07.767+0000] {logging_mixin.py:149} INFO - [2023-05-07T23:10:07.767+0000] {dagbag.py:541} INFO - Filling up the DagBag from /opt/airflow/dags/utils/fetching_best_model.py
[2023-05-07T23:10:07.773+0000] {logging_mixin.py:149} INFO - [2023-05-07T23:10:07.772+0000] {dagbag.py:350} ERROR - Failed to import: /opt/airflow/dags/utils/fetching_best_model.py
Traceback (most recent call last):
  File "/home/airflow/.local/lib/python3.7/site-packages/airflow/models/dagbag.py", line 346, in parse
    loader.exec_module(new_module)
  File "<frozen importlib._bootstrap_external>", line 728, in exec_module
  File "<frozen importlib._bootstrap>", line 219, in _call_with_frames_removed
  File "/opt/airflow/dags/utils/fetching_best_model.py", line 1, in <module>
    from sklearn.preprocessing import MinMaxScaler
ModuleNotFoundError: No module named 'sklearn'
[2023-05-07T23:10:07.775+0000] {processor.py:811} WARNING - No viable dags retrieved from /opt/airflow/dags/utils/fetching_best_model.py
[2023-05-07T23:10:07.829+0000] {processor.py:178} INFO - Processing /opt/airflow/dags/utils/fetching_best_model.py took 0.070 seconds
[2023-05-07T23:10:39.174+0000] {processor.py:156} INFO - Started process (PID=739) to work on /opt/airflow/dags/utils/fetching_best_model.py
[2023-05-07T23:10:39.175+0000] {processor.py:799} INFO - Processing file /opt/airflow/dags/utils/fetching_best_model.py for tasks to queue
[2023-05-07T23:10:39.176+0000] {logging_mixin.py:149} INFO - [2023-05-07T23:10:39.176+0000] {dagbag.py:541} INFO - Filling up the DagBag from /opt/airflow/dags/utils/fetching_best_model.py
[2023-05-07T23:10:39.180+0000] {logging_mixin.py:149} INFO - [2023-05-07T23:10:39.179+0000] {dagbag.py:350} ERROR - Failed to import: /opt/airflow/dags/utils/fetching_best_model.py
Traceback (most recent call last):
  File "/home/airflow/.local/lib/python3.7/site-packages/airflow/models/dagbag.py", line 346, in parse
    loader.exec_module(new_module)
  File "<frozen importlib._bootstrap_external>", line 728, in exec_module
  File "<frozen importlib._bootstrap>", line 219, in _call_with_frames_removed
  File "/opt/airflow/dags/utils/fetching_best_model.py", line 1, in <module>
    from sklearn.preprocessing import MinMaxScaler
ModuleNotFoundError: No module named 'sklearn'
[2023-05-07T23:10:39.181+0000] {processor.py:811} WARNING - No viable dags retrieved from /opt/airflow/dags/utils/fetching_best_model.py
[2023-05-07T23:10:39.205+0000] {processor.py:178} INFO - Processing /opt/airflow/dags/utils/fetching_best_model.py took 0.034 seconds
[2023-05-07T23:11:10.247+0000] {processor.py:156} INFO - Started process (PID=792) to work on /opt/airflow/dags/utils/fetching_best_model.py
[2023-05-07T23:11:10.248+0000] {processor.py:799} INFO - Processing file /opt/airflow/dags/utils/fetching_best_model.py for tasks to queue
[2023-05-07T23:11:10.249+0000] {logging_mixin.py:149} INFO - [2023-05-07T23:11:10.249+0000] {dagbag.py:541} INFO - Filling up the DagBag from /opt/airflow/dags/utils/fetching_best_model.py
[2023-05-07T23:11:10.254+0000] {logging_mixin.py:149} INFO - [2023-05-07T23:11:10.252+0000] {dagbag.py:350} ERROR - Failed to import: /opt/airflow/dags/utils/fetching_best_model.py
Traceback (most recent call last):
  File "/home/airflow/.local/lib/python3.7/site-packages/airflow/models/dagbag.py", line 346, in parse
    loader.exec_module(new_module)
  File "<frozen importlib._bootstrap_external>", line 728, in exec_module
  File "<frozen importlib._bootstrap>", line 219, in _call_with_frames_removed
  File "/opt/airflow/dags/utils/fetching_best_model.py", line 1, in <module>
    from sklearn.preprocessing import MinMaxScaler
ModuleNotFoundError: No module named 'sklearn'
[2023-05-07T23:11:10.254+0000] {processor.py:811} WARNING - No viable dags retrieved from /opt/airflow/dags/utils/fetching_best_model.py
[2023-05-07T23:11:10.272+0000] {processor.py:178} INFO - Processing /opt/airflow/dags/utils/fetching_best_model.py took 0.028 seconds
[2023-05-07T23:11:41.260+0000] {processor.py:156} INFO - Started process (PID=846) to work on /opt/airflow/dags/utils/fetching_best_model.py
[2023-05-07T23:11:41.261+0000] {processor.py:799} INFO - Processing file /opt/airflow/dags/utils/fetching_best_model.py for tasks to queue
[2023-05-07T23:11:41.262+0000] {logging_mixin.py:149} INFO - [2023-05-07T23:11:41.262+0000] {dagbag.py:541} INFO - Filling up the DagBag from /opt/airflow/dags/utils/fetching_best_model.py
[2023-05-07T23:11:41.266+0000] {logging_mixin.py:149} INFO - [2023-05-07T23:11:41.265+0000] {dagbag.py:350} ERROR - Failed to import: /opt/airflow/dags/utils/fetching_best_model.py
Traceback (most recent call last):
  File "/home/airflow/.local/lib/python3.7/site-packages/airflow/models/dagbag.py", line 346, in parse
    loader.exec_module(new_module)
  File "<frozen importlib._bootstrap_external>", line 728, in exec_module
  File "<frozen importlib._bootstrap>", line 219, in _call_with_frames_removed
  File "/opt/airflow/dags/utils/fetching_best_model.py", line 1, in <module>
    from sklearn.preprocessing import MinMaxScaler
ModuleNotFoundError: No module named 'sklearn'
[2023-05-07T23:11:41.267+0000] {processor.py:811} WARNING - No viable dags retrieved from /opt/airflow/dags/utils/fetching_best_model.py
[2023-05-07T23:11:41.282+0000] {processor.py:178} INFO - Processing /opt/airflow/dags/utils/fetching_best_model.py took 0.025 seconds
[2023-05-07T23:12:12.318+0000] {processor.py:156} INFO - Started process (PID=899) to work on /opt/airflow/dags/utils/fetching_best_model.py
[2023-05-07T23:12:12.319+0000] {processor.py:799} INFO - Processing file /opt/airflow/dags/utils/fetching_best_model.py for tasks to queue
[2023-05-07T23:12:12.320+0000] {logging_mixin.py:149} INFO - [2023-05-07T23:12:12.320+0000] {dagbag.py:541} INFO - Filling up the DagBag from /opt/airflow/dags/utils/fetching_best_model.py
[2023-05-07T23:12:12.325+0000] {logging_mixin.py:149} INFO - [2023-05-07T23:12:12.324+0000] {dagbag.py:350} ERROR - Failed to import: /opt/airflow/dags/utils/fetching_best_model.py
Traceback (most recent call last):
  File "/home/airflow/.local/lib/python3.7/site-packages/airflow/models/dagbag.py", line 346, in parse
    loader.exec_module(new_module)
  File "<frozen importlib._bootstrap_external>", line 728, in exec_module
  File "<frozen importlib._bootstrap>", line 219, in _call_with_frames_removed
  File "/opt/airflow/dags/utils/fetching_best_model.py", line 1, in <module>
    from sklearn.preprocessing import MinMaxScaler
ModuleNotFoundError: No module named 'sklearn'
[2023-05-07T23:12:12.325+0000] {processor.py:811} WARNING - No viable dags retrieved from /opt/airflow/dags/utils/fetching_best_model.py
[2023-05-07T23:12:12.343+0000] {processor.py:178} INFO - Processing /opt/airflow/dags/utils/fetching_best_model.py took 0.027 seconds
[2023-05-07T23:12:43.400+0000] {processor.py:156} INFO - Started process (PID=952) to work on /opt/airflow/dags/utils/fetching_best_model.py
[2023-05-07T23:12:43.401+0000] {processor.py:799} INFO - Processing file /opt/airflow/dags/utils/fetching_best_model.py for tasks to queue
[2023-05-07T23:12:43.402+0000] {logging_mixin.py:149} INFO - [2023-05-07T23:12:43.402+0000] {dagbag.py:541} INFO - Filling up the DagBag from /opt/airflow/dags/utils/fetching_best_model.py
[2023-05-07T23:12:43.406+0000] {logging_mixin.py:149} INFO - [2023-05-07T23:12:43.405+0000] {dagbag.py:350} ERROR - Failed to import: /opt/airflow/dags/utils/fetching_best_model.py
Traceback (most recent call last):
  File "/home/airflow/.local/lib/python3.7/site-packages/airflow/models/dagbag.py", line 346, in parse
    loader.exec_module(new_module)
  File "<frozen importlib._bootstrap_external>", line 728, in exec_module
  File "<frozen importlib._bootstrap>", line 219, in _call_with_frames_removed
  File "/opt/airflow/dags/utils/fetching_best_model.py", line 1, in <module>
    from sklearn.preprocessing import MinMaxScaler
ModuleNotFoundError: No module named 'sklearn'
[2023-05-07T23:12:43.407+0000] {processor.py:811} WARNING - No viable dags retrieved from /opt/airflow/dags/utils/fetching_best_model.py
[2023-05-07T23:12:43.423+0000] {processor.py:178} INFO - Processing /opt/airflow/dags/utils/fetching_best_model.py took 0.025 seconds
[2023-05-07T23:13:14.383+0000] {processor.py:156} INFO - Started process (PID=1005) to work on /opt/airflow/dags/utils/fetching_best_model.py
[2023-05-07T23:13:14.385+0000] {processor.py:799} INFO - Processing file /opt/airflow/dags/utils/fetching_best_model.py for tasks to queue
[2023-05-07T23:13:14.386+0000] {logging_mixin.py:149} INFO - [2023-05-07T23:13:14.386+0000] {dagbag.py:541} INFO - Filling up the DagBag from /opt/airflow/dags/utils/fetching_best_model.py
[2023-05-07T23:13:14.391+0000] {logging_mixin.py:149} INFO - [2023-05-07T23:13:14.390+0000] {dagbag.py:350} ERROR - Failed to import: /opt/airflow/dags/utils/fetching_best_model.py
Traceback (most recent call last):
  File "/home/airflow/.local/lib/python3.7/site-packages/airflow/models/dagbag.py", line 346, in parse
    loader.exec_module(new_module)
  File "<frozen importlib._bootstrap_external>", line 728, in exec_module
  File "<frozen importlib._bootstrap>", line 219, in _call_with_frames_removed
  File "/opt/airflow/dags/utils/fetching_best_model.py", line 1, in <module>
    from sklearn.preprocessing import MinMaxScaler
ModuleNotFoundError: No module named 'sklearn'
[2023-05-07T23:13:14.392+0000] {processor.py:811} WARNING - No viable dags retrieved from /opt/airflow/dags/utils/fetching_best_model.py
[2023-05-07T23:13:14.409+0000] {processor.py:178} INFO - Processing /opt/airflow/dags/utils/fetching_best_model.py took 0.028 seconds
[2023-05-07T23:13:45.381+0000] {processor.py:156} INFO - Started process (PID=1058) to work on /opt/airflow/dags/utils/fetching_best_model.py
[2023-05-07T23:13:45.383+0000] {processor.py:799} INFO - Processing file /opt/airflow/dags/utils/fetching_best_model.py for tasks to queue
[2023-05-07T23:13:45.384+0000] {logging_mixin.py:149} INFO - [2023-05-07T23:13:45.384+0000] {dagbag.py:541} INFO - Filling up the DagBag from /opt/airflow/dags/utils/fetching_best_model.py
[2023-05-07T23:13:45.389+0000] {logging_mixin.py:149} INFO - [2023-05-07T23:13:45.388+0000] {dagbag.py:350} ERROR - Failed to import: /opt/airflow/dags/utils/fetching_best_model.py
Traceback (most recent call last):
  File "/home/airflow/.local/lib/python3.7/site-packages/airflow/models/dagbag.py", line 346, in parse
    loader.exec_module(new_module)
  File "<frozen importlib._bootstrap_external>", line 728, in exec_module
  File "<frozen importlib._bootstrap>", line 219, in _call_with_frames_removed
  File "/opt/airflow/dags/utils/fetching_best_model.py", line 1, in <module>
    from sklearn.preprocessing import MinMaxScaler
ModuleNotFoundError: No module named 'sklearn'
[2023-05-07T23:13:45.390+0000] {processor.py:811} WARNING - No viable dags retrieved from /opt/airflow/dags/utils/fetching_best_model.py
[2023-05-07T23:13:45.408+0000] {processor.py:178} INFO - Processing /opt/airflow/dags/utils/fetching_best_model.py took 0.029 seconds
[2023-05-07T23:14:16.504+0000] {processor.py:156} INFO - Started process (PID=1111) to work on /opt/airflow/dags/utils/fetching_best_model.py
[2023-05-07T23:14:16.505+0000] {processor.py:799} INFO - Processing file /opt/airflow/dags/utils/fetching_best_model.py for tasks to queue
[2023-05-07T23:14:16.506+0000] {logging_mixin.py:149} INFO - [2023-05-07T23:14:16.506+0000] {dagbag.py:541} INFO - Filling up the DagBag from /opt/airflow/dags/utils/fetching_best_model.py
[2023-05-07T23:14:16.510+0000] {logging_mixin.py:149} INFO - [2023-05-07T23:14:16.509+0000] {dagbag.py:350} ERROR - Failed to import: /opt/airflow/dags/utils/fetching_best_model.py
Traceback (most recent call last):
  File "/home/airflow/.local/lib/python3.7/site-packages/airflow/models/dagbag.py", line 346, in parse
    loader.exec_module(new_module)
  File "<frozen importlib._bootstrap_external>", line 728, in exec_module
  File "<frozen importlib._bootstrap>", line 219, in _call_with_frames_removed
  File "/opt/airflow/dags/utils/fetching_best_model.py", line 1, in <module>
    from sklearn.preprocessing import MinMaxScaler
ModuleNotFoundError: No module named 'sklearn'
[2023-05-07T23:14:16.511+0000] {processor.py:811} WARNING - No viable dags retrieved from /opt/airflow/dags/utils/fetching_best_model.py
[2023-05-07T23:14:16.527+0000] {processor.py:178} INFO - Processing /opt/airflow/dags/utils/fetching_best_model.py took 0.026 seconds
[2023-05-07T23:14:47.768+0000] {processor.py:156} INFO - Started process (PID=1164) to work on /opt/airflow/dags/utils/fetching_best_model.py
[2023-05-07T23:14:47.769+0000] {processor.py:799} INFO - Processing file /opt/airflow/dags/utils/fetching_best_model.py for tasks to queue
[2023-05-07T23:14:47.770+0000] {logging_mixin.py:149} INFO - [2023-05-07T23:14:47.770+0000] {dagbag.py:541} INFO - Filling up the DagBag from /opt/airflow/dags/utils/fetching_best_model.py
[2023-05-07T23:14:47.775+0000] {logging_mixin.py:149} INFO - [2023-05-07T23:14:47.774+0000] {dagbag.py:350} ERROR - Failed to import: /opt/airflow/dags/utils/fetching_best_model.py
Traceback (most recent call last):
  File "/home/airflow/.local/lib/python3.7/site-packages/airflow/models/dagbag.py", line 346, in parse
    loader.exec_module(new_module)
  File "<frozen importlib._bootstrap_external>", line 728, in exec_module
  File "<frozen importlib._bootstrap>", line 219, in _call_with_frames_removed
  File "/opt/airflow/dags/utils/fetching_best_model.py", line 1, in <module>
    from sklearn.preprocessing import MinMaxScaler
ModuleNotFoundError: No module named 'sklearn'
[2023-05-07T23:14:47.775+0000] {processor.py:811} WARNING - No viable dags retrieved from /opt/airflow/dags/utils/fetching_best_model.py
[2023-05-07T23:14:47.812+0000] {processor.py:178} INFO - Processing /opt/airflow/dags/utils/fetching_best_model.py took 0.047 seconds
[2023-05-07T23:15:18.905+0000] {processor.py:156} INFO - Started process (PID=1217) to work on /opt/airflow/dags/utils/fetching_best_model.py
[2023-05-07T23:15:18.906+0000] {processor.py:799} INFO - Processing file /opt/airflow/dags/utils/fetching_best_model.py for tasks to queue
[2023-05-07T23:15:18.907+0000] {logging_mixin.py:149} INFO - [2023-05-07T23:15:18.907+0000] {dagbag.py:541} INFO - Filling up the DagBag from /opt/airflow/dags/utils/fetching_best_model.py
[2023-05-07T23:15:18.911+0000] {logging_mixin.py:149} INFO - [2023-05-07T23:15:18.910+0000] {dagbag.py:350} ERROR - Failed to import: /opt/airflow/dags/utils/fetching_best_model.py
Traceback (most recent call last):
  File "/home/airflow/.local/lib/python3.7/site-packages/airflow/models/dagbag.py", line 346, in parse
    loader.exec_module(new_module)
  File "<frozen importlib._bootstrap_external>", line 728, in exec_module
  File "<frozen importlib._bootstrap>", line 219, in _call_with_frames_removed
  File "/opt/airflow/dags/utils/fetching_best_model.py", line 1, in <module>
    from sklearn.preprocessing import MinMaxScaler
ModuleNotFoundError: No module named 'sklearn'
[2023-05-07T23:15:18.912+0000] {processor.py:811} WARNING - No viable dags retrieved from /opt/airflow/dags/utils/fetching_best_model.py
[2023-05-07T23:15:18.936+0000] {processor.py:178} INFO - Processing /opt/airflow/dags/utils/fetching_best_model.py took 0.033 seconds
[2023-05-07T23:15:50.033+0000] {processor.py:156} INFO - Started process (PID=1270) to work on /opt/airflow/dags/utils/fetching_best_model.py
[2023-05-07T23:15:50.035+0000] {processor.py:799} INFO - Processing file /opt/airflow/dags/utils/fetching_best_model.py for tasks to queue
[2023-05-07T23:15:50.035+0000] {logging_mixin.py:149} INFO - [2023-05-07T23:15:50.035+0000] {dagbag.py:541} INFO - Filling up the DagBag from /opt/airflow/dags/utils/fetching_best_model.py
[2023-05-07T23:15:50.041+0000] {logging_mixin.py:149} INFO - [2023-05-07T23:15:50.039+0000] {dagbag.py:350} ERROR - Failed to import: /opt/airflow/dags/utils/fetching_best_model.py
Traceback (most recent call last):
  File "/home/airflow/.local/lib/python3.7/site-packages/airflow/models/dagbag.py", line 346, in parse
    loader.exec_module(new_module)
  File "<frozen importlib._bootstrap_external>", line 728, in exec_module
  File "<frozen importlib._bootstrap>", line 219, in _call_with_frames_removed
  File "/opt/airflow/dags/utils/fetching_best_model.py", line 1, in <module>
    from sklearn.preprocessing import MinMaxScaler
ModuleNotFoundError: No module named 'sklearn'
[2023-05-07T23:15:50.041+0000] {processor.py:811} WARNING - No viable dags retrieved from /opt/airflow/dags/utils/fetching_best_model.py
[2023-05-07T23:15:50.059+0000] {processor.py:178} INFO - Processing /opt/airflow/dags/utils/fetching_best_model.py took 0.029 seconds
[2023-05-07T23:16:21.153+0000] {processor.py:156} INFO - Started process (PID=1323) to work on /opt/airflow/dags/utils/fetching_best_model.py
[2023-05-07T23:16:21.154+0000] {processor.py:799} INFO - Processing file /opt/airflow/dags/utils/fetching_best_model.py for tasks to queue
[2023-05-07T23:16:21.156+0000] {logging_mixin.py:149} INFO - [2023-05-07T23:16:21.156+0000] {dagbag.py:541} INFO - Filling up the DagBag from /opt/airflow/dags/utils/fetching_best_model.py
[2023-05-07T23:16:21.161+0000] {logging_mixin.py:149} INFO - [2023-05-07T23:16:21.160+0000] {dagbag.py:350} ERROR - Failed to import: /opt/airflow/dags/utils/fetching_best_model.py
Traceback (most recent call last):
  File "/home/airflow/.local/lib/python3.7/site-packages/airflow/models/dagbag.py", line 346, in parse
    loader.exec_module(new_module)
  File "<frozen importlib._bootstrap_external>", line 728, in exec_module
  File "<frozen importlib._bootstrap>", line 219, in _call_with_frames_removed
  File "/opt/airflow/dags/utils/fetching_best_model.py", line 1, in <module>
    from sklearn.preprocessing import MinMaxScaler
ModuleNotFoundError: No module named 'sklearn'
[2023-05-07T23:16:21.163+0000] {processor.py:811} WARNING - No viable dags retrieved from /opt/airflow/dags/utils/fetching_best_model.py
[2023-05-07T23:16:21.181+0000] {processor.py:178} INFO - Processing /opt/airflow/dags/utils/fetching_best_model.py took 0.030 seconds
[2023-05-07T23:16:52.271+0000] {processor.py:156} INFO - Started process (PID=1376) to work on /opt/airflow/dags/utils/fetching_best_model.py
[2023-05-07T23:16:52.272+0000] {processor.py:799} INFO - Processing file /opt/airflow/dags/utils/fetching_best_model.py for tasks to queue
[2023-05-07T23:16:52.273+0000] {logging_mixin.py:149} INFO - [2023-05-07T23:16:52.273+0000] {dagbag.py:541} INFO - Filling up the DagBag from /opt/airflow/dags/utils/fetching_best_model.py
[2023-05-07T23:16:52.278+0000] {logging_mixin.py:149} INFO - [2023-05-07T23:16:52.277+0000] {dagbag.py:350} ERROR - Failed to import: /opt/airflow/dags/utils/fetching_best_model.py
Traceback (most recent call last):
  File "/home/airflow/.local/lib/python3.7/site-packages/airflow/models/dagbag.py", line 346, in parse
    loader.exec_module(new_module)
  File "<frozen importlib._bootstrap_external>", line 728, in exec_module
  File "<frozen importlib._bootstrap>", line 219, in _call_with_frames_removed
  File "/opt/airflow/dags/utils/fetching_best_model.py", line 1, in <module>
    from sklearn.preprocessing import MinMaxScaler
ModuleNotFoundError: No module named 'sklearn'
[2023-05-07T23:16:52.278+0000] {processor.py:811} WARNING - No viable dags retrieved from /opt/airflow/dags/utils/fetching_best_model.py
[2023-05-07T23:16:52.304+0000] {processor.py:178} INFO - Processing /opt/airflow/dags/utils/fetching_best_model.py took 0.035 seconds
[2023-05-07T23:21:18.881+0000] {processor.py:156} INFO - Started process (PID=50) to work on /opt/airflow/dags/utils/fetching_best_model.py
[2023-05-07T23:21:18.887+0000] {processor.py:799} INFO - Processing file /opt/airflow/dags/utils/fetching_best_model.py for tasks to queue
[2023-05-07T23:21:18.890+0000] {logging_mixin.py:149} INFO - [2023-05-07T23:21:18.890+0000] {dagbag.py:541} INFO - Filling up the DagBag from /opt/airflow/dags/utils/fetching_best_model.py
[2023-05-07T23:21:24.968+0000] {logging_mixin.py:149} WARNING - /home/airflow/.local/lib/python3.7/site-packages/tensorflow_io/python/ops/__init__.py:98 UserWarning: unable to load libtensorflow_io_plugins.so: unable to open file: libtensorflow_io_plugins.so, from paths: ['/home/airflow/.local/lib/python3.7/site-packages/tensorflow_io/python/ops/libtensorflow_io_plugins.so']
caused by: ["[Errno 2] The file to load file system plugin from does not exist.: '/home/airflow/.local/lib/python3.7/site-packages/tensorflow_io/python/ops/libtensorflow_io_plugins.so'"]
[2023-05-07T23:21:24.978+0000] {logging_mixin.py:149} WARNING - /home/airflow/.local/lib/python3.7/site-packages/tensorflow_io/python/ops/__init__.py:104 UserWarning: file system plugins are not loaded: unable to open file: libtensorflow_io.so, from paths: ['/home/airflow/.local/lib/python3.7/site-packages/tensorflow_io/python/ops/libtensorflow_io.so']
caused by: ['/home/airflow/.local/lib/python3.7/site-packages/tensorflow_io/python/ops/libtensorflow_io.so: cannot open shared object file: No such file or directory']
[2023-05-07T23:21:25.417+0000] {processor.py:811} WARNING - No viable dags retrieved from /opt/airflow/dags/utils/fetching_best_model.py
[2023-05-07T23:21:25.456+0000] {processor.py:178} INFO - Processing /opt/airflow/dags/utils/fetching_best_model.py took 6.578 seconds
[2023-05-07T23:21:55.786+0000] {processor.py:156} INFO - Started process (PID=138) to work on /opt/airflow/dags/utils/fetching_best_model.py
[2023-05-07T23:21:55.789+0000] {processor.py:799} INFO - Processing file /opt/airflow/dags/utils/fetching_best_model.py for tasks to queue
[2023-05-07T23:21:55.791+0000] {logging_mixin.py:149} INFO - [2023-05-07T23:21:55.791+0000] {dagbag.py:541} INFO - Filling up the DagBag from /opt/airflow/dags/utils/fetching_best_model.py
[2023-05-07T23:21:58.100+0000] {logging_mixin.py:149} WARNING - /home/airflow/.local/lib/python3.7/site-packages/tensorflow_io/python/ops/__init__.py:98 UserWarning: unable to load libtensorflow_io_plugins.so: unable to open file: libtensorflow_io_plugins.so, from paths: ['/home/airflow/.local/lib/python3.7/site-packages/tensorflow_io/python/ops/libtensorflow_io_plugins.so']
caused by: ["[Errno 2] The file to load file system plugin from does not exist.: '/home/airflow/.local/lib/python3.7/site-packages/tensorflow_io/python/ops/libtensorflow_io_plugins.so'"]
[2023-05-07T23:21:58.103+0000] {logging_mixin.py:149} WARNING - /home/airflow/.local/lib/python3.7/site-packages/tensorflow_io/python/ops/__init__.py:104 UserWarning: file system plugins are not loaded: unable to open file: libtensorflow_io.so, from paths: ['/home/airflow/.local/lib/python3.7/site-packages/tensorflow_io/python/ops/libtensorflow_io.so']
caused by: ['/home/airflow/.local/lib/python3.7/site-packages/tensorflow_io/python/ops/libtensorflow_io.so: cannot open shared object file: No such file or directory']
[2023-05-07T23:21:58.514+0000] {processor.py:811} WARNING - No viable dags retrieved from /opt/airflow/dags/utils/fetching_best_model.py
[2023-05-07T23:21:58.528+0000] {processor.py:178} INFO - Processing /opt/airflow/dags/utils/fetching_best_model.py took 2.748 seconds
[2023-05-07T23:22:28.728+0000] {processor.py:156} INFO - Started process (PID=208) to work on /opt/airflow/dags/utils/fetching_best_model.py
[2023-05-07T23:22:28.730+0000] {processor.py:799} INFO - Processing file /opt/airflow/dags/utils/fetching_best_model.py for tasks to queue
[2023-05-07T23:22:28.731+0000] {logging_mixin.py:149} INFO - [2023-05-07T23:22:28.731+0000] {dagbag.py:541} INFO - Filling up the DagBag from /opt/airflow/dags/utils/fetching_best_model.py
[2023-05-07T23:22:30.026+0000] {logging_mixin.py:149} WARNING - /home/airflow/.local/lib/python3.7/site-packages/tensorflow_io/python/ops/__init__.py:98 UserWarning: unable to load libtensorflow_io_plugins.so: unable to open file: libtensorflow_io_plugins.so, from paths: ['/home/airflow/.local/lib/python3.7/site-packages/tensorflow_io/python/ops/libtensorflow_io_plugins.so']
caused by: ["[Errno 2] The file to load file system plugin from does not exist.: '/home/airflow/.local/lib/python3.7/site-packages/tensorflow_io/python/ops/libtensorflow_io_plugins.so'"]
[2023-05-07T23:22:30.028+0000] {logging_mixin.py:149} WARNING - /home/airflow/.local/lib/python3.7/site-packages/tensorflow_io/python/ops/__init__.py:104 UserWarning: file system plugins are not loaded: unable to open file: libtensorflow_io.so, from paths: ['/home/airflow/.local/lib/python3.7/site-packages/tensorflow_io/python/ops/libtensorflow_io.so']
caused by: ['/home/airflow/.local/lib/python3.7/site-packages/tensorflow_io/python/ops/libtensorflow_io.so: cannot open shared object file: No such file or directory']
[2023-05-07T23:22:30.110+0000] {processor.py:811} WARNING - No viable dags retrieved from /opt/airflow/dags/utils/fetching_best_model.py
[2023-05-07T23:22:30.121+0000] {processor.py:178} INFO - Processing /opt/airflow/dags/utils/fetching_best_model.py took 1.399 seconds
[2023-05-07T23:23:00.206+0000] {processor.py:156} INFO - Started process (PID=269) to work on /opt/airflow/dags/utils/fetching_best_model.py
[2023-05-07T23:23:00.208+0000] {processor.py:799} INFO - Processing file /opt/airflow/dags/utils/fetching_best_model.py for tasks to queue
[2023-05-07T23:23:00.209+0000] {logging_mixin.py:149} INFO - [2023-05-07T23:23:00.209+0000] {dagbag.py:541} INFO - Filling up the DagBag from /opt/airflow/dags/utils/fetching_best_model.py
[2023-05-07T23:23:02.028+0000] {logging_mixin.py:149} WARNING - /home/airflow/.local/lib/python3.7/site-packages/tensorflow_io/python/ops/__init__.py:98 UserWarning: unable to load libtensorflow_io_plugins.so: unable to open file: libtensorflow_io_plugins.so, from paths: ['/home/airflow/.local/lib/python3.7/site-packages/tensorflow_io/python/ops/libtensorflow_io_plugins.so']
caused by: ["[Errno 2] The file to load file system plugin from does not exist.: '/home/airflow/.local/lib/python3.7/site-packages/tensorflow_io/python/ops/libtensorflow_io_plugins.so'"]
[2023-05-07T23:23:02.031+0000] {logging_mixin.py:149} WARNING - /home/airflow/.local/lib/python3.7/site-packages/tensorflow_io/python/ops/__init__.py:104 UserWarning: file system plugins are not loaded: unable to open file: libtensorflow_io.so, from paths: ['/home/airflow/.local/lib/python3.7/site-packages/tensorflow_io/python/ops/libtensorflow_io.so']
caused by: ['/home/airflow/.local/lib/python3.7/site-packages/tensorflow_io/python/ops/libtensorflow_io.so: cannot open shared object file: No such file or directory']
[2023-05-07T23:23:02.164+0000] {processor.py:811} WARNING - No viable dags retrieved from /opt/airflow/dags/utils/fetching_best_model.py
[2023-05-07T23:23:02.178+0000] {processor.py:178} INFO - Processing /opt/airflow/dags/utils/fetching_best_model.py took 1.975 seconds
[2023-05-07T23:23:32.545+0000] {processor.py:156} INFO - Started process (PID=330) to work on /opt/airflow/dags/utils/fetching_best_model.py
[2023-05-07T23:23:32.547+0000] {processor.py:799} INFO - Processing file /opt/airflow/dags/utils/fetching_best_model.py for tasks to queue
[2023-05-07T23:23:32.548+0000] {logging_mixin.py:149} INFO - [2023-05-07T23:23:32.548+0000] {dagbag.py:541} INFO - Filling up the DagBag from /opt/airflow/dags/utils/fetching_best_model.py
[2023-05-07T23:23:33.873+0000] {logging_mixin.py:149} WARNING - /home/airflow/.local/lib/python3.7/site-packages/tensorflow_io/python/ops/__init__.py:98 UserWarning: unable to load libtensorflow_io_plugins.so: unable to open file: libtensorflow_io_plugins.so, from paths: ['/home/airflow/.local/lib/python3.7/site-packages/tensorflow_io/python/ops/libtensorflow_io_plugins.so']
caused by: ["[Errno 2] The file to load file system plugin from does not exist.: '/home/airflow/.local/lib/python3.7/site-packages/tensorflow_io/python/ops/libtensorflow_io_plugins.so'"]
[2023-05-07T23:23:33.876+0000] {logging_mixin.py:149} WARNING - /home/airflow/.local/lib/python3.7/site-packages/tensorflow_io/python/ops/__init__.py:104 UserWarning: file system plugins are not loaded: unable to open file: libtensorflow_io.so, from paths: ['/home/airflow/.local/lib/python3.7/site-packages/tensorflow_io/python/ops/libtensorflow_io.so']
caused by: ['/home/airflow/.local/lib/python3.7/site-packages/tensorflow_io/python/ops/libtensorflow_io.so: cannot open shared object file: No such file or directory']
[2023-05-07T23:23:33.967+0000] {processor.py:811} WARNING - No viable dags retrieved from /opt/airflow/dags/utils/fetching_best_model.py
[2023-05-07T23:23:33.984+0000] {processor.py:178} INFO - Processing /opt/airflow/dags/utils/fetching_best_model.py took 1.444 seconds
[2023-05-07T23:24:04.299+0000] {processor.py:156} INFO - Started process (PID=391) to work on /opt/airflow/dags/utils/fetching_best_model.py
[2023-05-07T23:24:04.301+0000] {processor.py:799} INFO - Processing file /opt/airflow/dags/utils/fetching_best_model.py for tasks to queue
[2023-05-07T23:24:04.303+0000] {logging_mixin.py:149} INFO - [2023-05-07T23:24:04.303+0000] {dagbag.py:541} INFO - Filling up the DagBag from /opt/airflow/dags/utils/fetching_best_model.py
[2023-05-07T23:24:05.584+0000] {logging_mixin.py:149} WARNING - /home/airflow/.local/lib/python3.7/site-packages/tensorflow_io/python/ops/__init__.py:98 UserWarning: unable to load libtensorflow_io_plugins.so: unable to open file: libtensorflow_io_plugins.so, from paths: ['/home/airflow/.local/lib/python3.7/site-packages/tensorflow_io/python/ops/libtensorflow_io_plugins.so']
caused by: ["[Errno 2] The file to load file system plugin from does not exist.: '/home/airflow/.local/lib/python3.7/site-packages/tensorflow_io/python/ops/libtensorflow_io_plugins.so'"]
[2023-05-07T23:24:05.586+0000] {logging_mixin.py:149} WARNING - /home/airflow/.local/lib/python3.7/site-packages/tensorflow_io/python/ops/__init__.py:104 UserWarning: file system plugins are not loaded: unable to open file: libtensorflow_io.so, from paths: ['/home/airflow/.local/lib/python3.7/site-packages/tensorflow_io/python/ops/libtensorflow_io.so']
caused by: ['/home/airflow/.local/lib/python3.7/site-packages/tensorflow_io/python/ops/libtensorflow_io.so: cannot open shared object file: No such file or directory']
[2023-05-07T23:24:05.660+0000] {processor.py:811} WARNING - No viable dags retrieved from /opt/airflow/dags/utils/fetching_best_model.py
[2023-05-07T23:24:05.670+0000] {processor.py:178} INFO - Processing /opt/airflow/dags/utils/fetching_best_model.py took 1.376 seconds
[2023-05-07T23:24:36.436+0000] {processor.py:156} INFO - Started process (PID=470) to work on /opt/airflow/dags/utils/fetching_best_model.py
[2023-05-07T23:24:36.448+0000] {processor.py:799} INFO - Processing file /opt/airflow/dags/utils/fetching_best_model.py for tasks to queue
[2023-05-07T23:24:36.451+0000] {logging_mixin.py:149} INFO - [2023-05-07T23:24:36.451+0000] {dagbag.py:541} INFO - Filling up the DagBag from /opt/airflow/dags/utils/fetching_best_model.py
[2023-05-07T23:24:38.852+0000] {logging_mixin.py:149} WARNING - /home/airflow/.local/lib/python3.7/site-packages/tensorflow_io/python/ops/__init__.py:98 UserWarning: unable to load libtensorflow_io_plugins.so: unable to open file: libtensorflow_io_plugins.so, from paths: ['/home/airflow/.local/lib/python3.7/site-packages/tensorflow_io/python/ops/libtensorflow_io_plugins.so']
caused by: ["[Errno 2] The file to load file system plugin from does not exist.: '/home/airflow/.local/lib/python3.7/site-packages/tensorflow_io/python/ops/libtensorflow_io_plugins.so'"]
[2023-05-07T23:24:38.857+0000] {logging_mixin.py:149} WARNING - /home/airflow/.local/lib/python3.7/site-packages/tensorflow_io/python/ops/__init__.py:104 UserWarning: file system plugins are not loaded: unable to open file: libtensorflow_io.so, from paths: ['/home/airflow/.local/lib/python3.7/site-packages/tensorflow_io/python/ops/libtensorflow_io.so']
caused by: ['/home/airflow/.local/lib/python3.7/site-packages/tensorflow_io/python/ops/libtensorflow_io.so: cannot open shared object file: No such file or directory']
[2023-05-07T23:24:39.008+0000] {processor.py:811} WARNING - No viable dags retrieved from /opt/airflow/dags/utils/fetching_best_model.py
[2023-05-07T23:24:39.032+0000] {processor.py:178} INFO - Processing /opt/airflow/dags/utils/fetching_best_model.py took 2.599 seconds
[2023-05-07T23:25:09.751+0000] {processor.py:156} INFO - Started process (PID=538) to work on /opt/airflow/dags/utils/fetching_best_model.py
[2023-05-07T23:25:09.753+0000] {processor.py:799} INFO - Processing file /opt/airflow/dags/utils/fetching_best_model.py for tasks to queue
[2023-05-07T23:25:09.755+0000] {logging_mixin.py:149} INFO - [2023-05-07T23:25:09.754+0000] {dagbag.py:541} INFO - Filling up the DagBag from /opt/airflow/dags/utils/fetching_best_model.py
[2023-05-07T23:26:18.564+0000] {processor.py:156} INFO - Started process (PID=49) to work on /opt/airflow/dags/utils/fetching_best_model.py
[2023-05-07T23:26:18.567+0000] {processor.py:799} INFO - Processing file /opt/airflow/dags/utils/fetching_best_model.py for tasks to queue
[2023-05-07T23:26:18.568+0000] {logging_mixin.py:149} INFO - [2023-05-07T23:26:18.568+0000] {dagbag.py:541} INFO - Filling up the DagBag from /opt/airflow/dags/utils/fetching_best_model.py
[2023-05-07T23:26:20.800+0000] {logging_mixin.py:149} WARNING - /home/airflow/.local/lib/python3.7/site-packages/tensorflow_io/python/ops/__init__.py:98 UserWarning: unable to load libtensorflow_io_plugins.so: unable to open file: libtensorflow_io_plugins.so, from paths: ['/home/airflow/.local/lib/python3.7/site-packages/tensorflow_io/python/ops/libtensorflow_io_plugins.so']
caused by: ["[Errno 2] The file to load file system plugin from does not exist.: '/home/airflow/.local/lib/python3.7/site-packages/tensorflow_io/python/ops/libtensorflow_io_plugins.so'"]
[2023-05-07T23:26:20.802+0000] {logging_mixin.py:149} WARNING - /home/airflow/.local/lib/python3.7/site-packages/tensorflow_io/python/ops/__init__.py:104 UserWarning: file system plugins are not loaded: unable to open file: libtensorflow_io.so, from paths: ['/home/airflow/.local/lib/python3.7/site-packages/tensorflow_io/python/ops/libtensorflow_io.so']
caused by: ['/home/airflow/.local/lib/python3.7/site-packages/tensorflow_io/python/ops/libtensorflow_io.so: cannot open shared object file: No such file or directory']
[2023-05-07T23:26:20.942+0000] {processor.py:811} WARNING - No viable dags retrieved from /opt/airflow/dags/utils/fetching_best_model.py
[2023-05-07T23:26:20.973+0000] {processor.py:178} INFO - Processing /opt/airflow/dags/utils/fetching_best_model.py took 2.413 seconds
[2023-05-07T23:26:51.185+0000] {processor.py:156} INFO - Started process (PID=109) to work on /opt/airflow/dags/utils/fetching_best_model.py
[2023-05-07T23:26:51.186+0000] {processor.py:799} INFO - Processing file /opt/airflow/dags/utils/fetching_best_model.py for tasks to queue
[2023-05-07T23:26:51.187+0000] {logging_mixin.py:149} INFO - [2023-05-07T23:26:51.187+0000] {dagbag.py:541} INFO - Filling up the DagBag from /opt/airflow/dags/utils/fetching_best_model.py
[2023-05-07T23:26:52.585+0000] {logging_mixin.py:149} WARNING - /home/airflow/.local/lib/python3.7/site-packages/tensorflow_io/python/ops/__init__.py:98 UserWarning: unable to load libtensorflow_io_plugins.so: unable to open file: libtensorflow_io_plugins.so, from paths: ['/home/airflow/.local/lib/python3.7/site-packages/tensorflow_io/python/ops/libtensorflow_io_plugins.so']
caused by: ["[Errno 2] The file to load file system plugin from does not exist.: '/home/airflow/.local/lib/python3.7/site-packages/tensorflow_io/python/ops/libtensorflow_io_plugins.so'"]
[2023-05-07T23:26:52.588+0000] {logging_mixin.py:149} WARNING - /home/airflow/.local/lib/python3.7/site-packages/tensorflow_io/python/ops/__init__.py:104 UserWarning: file system plugins are not loaded: unable to open file: libtensorflow_io.so, from paths: ['/home/airflow/.local/lib/python3.7/site-packages/tensorflow_io/python/ops/libtensorflow_io.so']
caused by: ['/home/airflow/.local/lib/python3.7/site-packages/tensorflow_io/python/ops/libtensorflow_io.so: cannot open shared object file: No such file or directory']
[2023-05-07T23:26:52.779+0000] {processor.py:811} WARNING - No viable dags retrieved from /opt/airflow/dags/utils/fetching_best_model.py
[2023-05-07T23:26:52.790+0000] {processor.py:178} INFO - Processing /opt/airflow/dags/utils/fetching_best_model.py took 1.608 seconds
[2023-05-07T23:27:22.952+0000] {processor.py:156} INFO - Started process (PID=184) to work on /opt/airflow/dags/utils/fetching_best_model.py
[2023-05-07T23:27:22.956+0000] {processor.py:799} INFO - Processing file /opt/airflow/dags/utils/fetching_best_model.py for tasks to queue
[2023-05-07T23:27:22.960+0000] {logging_mixin.py:149} INFO - [2023-05-07T23:27:22.959+0000] {dagbag.py:541} INFO - Filling up the DagBag from /opt/airflow/dags/utils/fetching_best_model.py
[2023-05-07T23:27:24.657+0000] {logging_mixin.py:149} WARNING - /home/airflow/.local/lib/python3.7/site-packages/tensorflow_io/python/ops/__init__.py:98 UserWarning: unable to load libtensorflow_io_plugins.so: unable to open file: libtensorflow_io_plugins.so, from paths: ['/home/airflow/.local/lib/python3.7/site-packages/tensorflow_io/python/ops/libtensorflow_io_plugins.so']
caused by: ["[Errno 2] The file to load file system plugin from does not exist.: '/home/airflow/.local/lib/python3.7/site-packages/tensorflow_io/python/ops/libtensorflow_io_plugins.so'"]
[2023-05-07T23:27:24.659+0000] {logging_mixin.py:149} WARNING - /home/airflow/.local/lib/python3.7/site-packages/tensorflow_io/python/ops/__init__.py:104 UserWarning: file system plugins are not loaded: unable to open file: libtensorflow_io.so, from paths: ['/home/airflow/.local/lib/python3.7/site-packages/tensorflow_io/python/ops/libtensorflow_io.so']
caused by: ['/home/airflow/.local/lib/python3.7/site-packages/tensorflow_io/python/ops/libtensorflow_io.so: cannot open shared object file: No such file or directory']
[2023-05-07T23:27:24.862+0000] {processor.py:811} WARNING - No viable dags retrieved from /opt/airflow/dags/utils/fetching_best_model.py
[2023-05-07T23:27:24.890+0000] {processor.py:178} INFO - Processing /opt/airflow/dags/utils/fetching_best_model.py took 1.941 seconds
[2023-05-07T23:27:55.111+0000] {processor.py:156} INFO - Started process (PID=244) to work on /opt/airflow/dags/utils/fetching_best_model.py
[2023-05-07T23:27:55.113+0000] {processor.py:799} INFO - Processing file /opt/airflow/dags/utils/fetching_best_model.py for tasks to queue
[2023-05-07T23:27:55.116+0000] {logging_mixin.py:149} INFO - [2023-05-07T23:27:55.115+0000] {dagbag.py:541} INFO - Filling up the DagBag from /opt/airflow/dags/utils/fetching_best_model.py
[2023-05-07T23:27:56.694+0000] {logging_mixin.py:149} WARNING - /home/airflow/.local/lib/python3.7/site-packages/tensorflow_io/python/ops/__init__.py:98 UserWarning: unable to load libtensorflow_io_plugins.so: unable to open file: libtensorflow_io_plugins.so, from paths: ['/home/airflow/.local/lib/python3.7/site-packages/tensorflow_io/python/ops/libtensorflow_io_plugins.so']
caused by: ["[Errno 2] The file to load file system plugin from does not exist.: '/home/airflow/.local/lib/python3.7/site-packages/tensorflow_io/python/ops/libtensorflow_io_plugins.so'"]
[2023-05-07T23:27:56.697+0000] {logging_mixin.py:149} WARNING - /home/airflow/.local/lib/python3.7/site-packages/tensorflow_io/python/ops/__init__.py:104 UserWarning: file system plugins are not loaded: unable to open file: libtensorflow_io.so, from paths: ['/home/airflow/.local/lib/python3.7/site-packages/tensorflow_io/python/ops/libtensorflow_io.so']
caused by: ['/home/airflow/.local/lib/python3.7/site-packages/tensorflow_io/python/ops/libtensorflow_io.so: cannot open shared object file: No such file or directory']
[2023-05-07T23:27:56.866+0000] {processor.py:811} WARNING - No viable dags retrieved from /opt/airflow/dags/utils/fetching_best_model.py
[2023-05-07T23:27:56.876+0000] {processor.py:178} INFO - Processing /opt/airflow/dags/utils/fetching_best_model.py took 1.770 seconds
[2023-05-07T23:28:27.108+0000] {processor.py:156} INFO - Started process (PID=305) to work on /opt/airflow/dags/utils/fetching_best_model.py
[2023-05-07T23:28:27.110+0000] {processor.py:799} INFO - Processing file /opt/airflow/dags/utils/fetching_best_model.py for tasks to queue
[2023-05-07T23:28:27.111+0000] {logging_mixin.py:149} INFO - [2023-05-07T23:28:27.111+0000] {dagbag.py:541} INFO - Filling up the DagBag from /opt/airflow/dags/utils/fetching_best_model.py
[2023-05-07T23:28:28.494+0000] {logging_mixin.py:149} WARNING - /home/airflow/.local/lib/python3.7/site-packages/tensorflow_io/python/ops/__init__.py:98 UserWarning: unable to load libtensorflow_io_plugins.so: unable to open file: libtensorflow_io_plugins.so, from paths: ['/home/airflow/.local/lib/python3.7/site-packages/tensorflow_io/python/ops/libtensorflow_io_plugins.so']
caused by: ["[Errno 2] The file to load file system plugin from does not exist.: '/home/airflow/.local/lib/python3.7/site-packages/tensorflow_io/python/ops/libtensorflow_io_plugins.so'"]
[2023-05-07T23:28:28.496+0000] {logging_mixin.py:149} WARNING - /home/airflow/.local/lib/python3.7/site-packages/tensorflow_io/python/ops/__init__.py:104 UserWarning: file system plugins are not loaded: unable to open file: libtensorflow_io.so, from paths: ['/home/airflow/.local/lib/python3.7/site-packages/tensorflow_io/python/ops/libtensorflow_io.so']
caused by: ['/home/airflow/.local/lib/python3.7/site-packages/tensorflow_io/python/ops/libtensorflow_io.so: cannot open shared object file: No such file or directory']
[2023-05-07T23:28:28.579+0000] {processor.py:811} WARNING - No viable dags retrieved from /opt/airflow/dags/utils/fetching_best_model.py
[2023-05-07T23:28:28.592+0000] {processor.py:178} INFO - Processing /opt/airflow/dags/utils/fetching_best_model.py took 1.491 seconds
[2023-05-07T23:28:59.267+0000] {processor.py:156} INFO - Started process (PID=370) to work on /opt/airflow/dags/utils/fetching_best_model.py
[2023-05-07T23:28:59.269+0000] {processor.py:799} INFO - Processing file /opt/airflow/dags/utils/fetching_best_model.py for tasks to queue
[2023-05-07T23:28:59.270+0000] {logging_mixin.py:149} INFO - [2023-05-07T23:28:59.270+0000] {dagbag.py:541} INFO - Filling up the DagBag from /opt/airflow/dags/utils/fetching_best_model.py
[2023-05-07T23:29:00.632+0000] {logging_mixin.py:149} WARNING - /home/airflow/.local/lib/python3.7/site-packages/tensorflow_io/python/ops/__init__.py:98 UserWarning: unable to load libtensorflow_io_plugins.so: unable to open file: libtensorflow_io_plugins.so, from paths: ['/home/airflow/.local/lib/python3.7/site-packages/tensorflow_io/python/ops/libtensorflow_io_plugins.so']
caused by: ["[Errno 2] The file to load file system plugin from does not exist.: '/home/airflow/.local/lib/python3.7/site-packages/tensorflow_io/python/ops/libtensorflow_io_plugins.so'"]
[2023-05-07T23:29:00.635+0000] {logging_mixin.py:149} WARNING - /home/airflow/.local/lib/python3.7/site-packages/tensorflow_io/python/ops/__init__.py:104 UserWarning: file system plugins are not loaded: unable to open file: libtensorflow_io.so, from paths: ['/home/airflow/.local/lib/python3.7/site-packages/tensorflow_io/python/ops/libtensorflow_io.so']
caused by: ['/home/airflow/.local/lib/python3.7/site-packages/tensorflow_io/python/ops/libtensorflow_io.so: cannot open shared object file: No such file or directory']
[2023-05-07T23:29:00.807+0000] {processor.py:811} WARNING - No viable dags retrieved from /opt/airflow/dags/utils/fetching_best_model.py
[2023-05-07T23:29:00.818+0000] {processor.py:178} INFO - Processing /opt/airflow/dags/utils/fetching_best_model.py took 1.556 seconds
[2023-05-07T23:29:31.083+0000] {processor.py:156} INFO - Started process (PID=425) to work on /opt/airflow/dags/utils/fetching_best_model.py
[2023-05-07T23:29:31.085+0000] {processor.py:799} INFO - Processing file /opt/airflow/dags/utils/fetching_best_model.py for tasks to queue
[2023-05-07T23:29:31.087+0000] {logging_mixin.py:149} INFO - [2023-05-07T23:29:31.087+0000] {dagbag.py:541} INFO - Filling up the DagBag from /opt/airflow/dags/utils/fetching_best_model.py
[2023-05-07T23:29:32.433+0000] {logging_mixin.py:149} WARNING - /home/airflow/.local/lib/python3.7/site-packages/tensorflow_io/python/ops/__init__.py:98 UserWarning: unable to load libtensorflow_io_plugins.so: unable to open file: libtensorflow_io_plugins.so, from paths: ['/home/airflow/.local/lib/python3.7/site-packages/tensorflow_io/python/ops/libtensorflow_io_plugins.so']
caused by: ["[Errno 2] The file to load file system plugin from does not exist.: '/home/airflow/.local/lib/python3.7/site-packages/tensorflow_io/python/ops/libtensorflow_io_plugins.so'"]
[2023-05-07T23:29:32.435+0000] {logging_mixin.py:149} WARNING - /home/airflow/.local/lib/python3.7/site-packages/tensorflow_io/python/ops/__init__.py:104 UserWarning: file system plugins are not loaded: unable to open file: libtensorflow_io.so, from paths: ['/home/airflow/.local/lib/python3.7/site-packages/tensorflow_io/python/ops/libtensorflow_io.so']
caused by: ['/home/airflow/.local/lib/python3.7/site-packages/tensorflow_io/python/ops/libtensorflow_io.so: cannot open shared object file: No such file or directory']
[2023-05-07T23:29:32.603+0000] {processor.py:811} WARNING - No viable dags retrieved from /opt/airflow/dags/utils/fetching_best_model.py
[2023-05-07T23:29:32.614+0000] {processor.py:178} INFO - Processing /opt/airflow/dags/utils/fetching_best_model.py took 1.535 seconds
[2023-05-07T23:30:03.265+0000] {processor.py:156} INFO - Started process (PID=462) to work on /opt/airflow/dags/utils/fetching_best_model.py
[2023-05-07T23:30:03.266+0000] {processor.py:799} INFO - Processing file /opt/airflow/dags/utils/fetching_best_model.py for tasks to queue
[2023-05-07T23:30:03.268+0000] {logging_mixin.py:149} INFO - [2023-05-07T23:30:03.268+0000] {dagbag.py:541} INFO - Filling up the DagBag from /opt/airflow/dags/utils/fetching_best_model.py
[2023-05-07T23:30:04.600+0000] {logging_mixin.py:149} WARNING - /home/airflow/.local/lib/python3.7/site-packages/tensorflow_io/python/ops/__init__.py:98 UserWarning: unable to load libtensorflow_io_plugins.so: unable to open file: libtensorflow_io_plugins.so, from paths: ['/home/airflow/.local/lib/python3.7/site-packages/tensorflow_io/python/ops/libtensorflow_io_plugins.so']
caused by: ["[Errno 2] The file to load file system plugin from does not exist.: '/home/airflow/.local/lib/python3.7/site-packages/tensorflow_io/python/ops/libtensorflow_io_plugins.so'"]
[2023-05-07T23:30:04.602+0000] {logging_mixin.py:149} WARNING - /home/airflow/.local/lib/python3.7/site-packages/tensorflow_io/python/ops/__init__.py:104 UserWarning: file system plugins are not loaded: unable to open file: libtensorflow_io.so, from paths: ['/home/airflow/.local/lib/python3.7/site-packages/tensorflow_io/python/ops/libtensorflow_io.so']
caused by: ['/home/airflow/.local/lib/python3.7/site-packages/tensorflow_io/python/ops/libtensorflow_io.so: cannot open shared object file: No such file or directory']
[2023-05-07T23:30:04.769+0000] {processor.py:811} WARNING - No viable dags retrieved from /opt/airflow/dags/utils/fetching_best_model.py
[2023-05-07T23:30:04.779+0000] {processor.py:178} INFO - Processing /opt/airflow/dags/utils/fetching_best_model.py took 1.519 seconds
[2023-05-07T23:30:35.533+0000] {processor.py:156} INFO - Started process (PID=507) to work on /opt/airflow/dags/utils/fetching_best_model.py
[2023-05-07T23:30:35.538+0000] {processor.py:799} INFO - Processing file /opt/airflow/dags/utils/fetching_best_model.py for tasks to queue
[2023-05-07T23:30:35.540+0000] {logging_mixin.py:149} INFO - [2023-05-07T23:30:35.540+0000] {dagbag.py:541} INFO - Filling up the DagBag from /opt/airflow/dags/utils/fetching_best_model.py
[2023-05-07T23:30:36.928+0000] {logging_mixin.py:149} WARNING - /home/airflow/.local/lib/python3.7/site-packages/tensorflow_io/python/ops/__init__.py:98 UserWarning: unable to load libtensorflow_io_plugins.so: unable to open file: libtensorflow_io_plugins.so, from paths: ['/home/airflow/.local/lib/python3.7/site-packages/tensorflow_io/python/ops/libtensorflow_io_plugins.so']
caused by: ["[Errno 2] The file to load file system plugin from does not exist.: '/home/airflow/.local/lib/python3.7/site-packages/tensorflow_io/python/ops/libtensorflow_io_plugins.so'"]
[2023-05-07T23:30:36.930+0000] {logging_mixin.py:149} WARNING - /home/airflow/.local/lib/python3.7/site-packages/tensorflow_io/python/ops/__init__.py:104 UserWarning: file system plugins are not loaded: unable to open file: libtensorflow_io.so, from paths: ['/home/airflow/.local/lib/python3.7/site-packages/tensorflow_io/python/ops/libtensorflow_io.so']
caused by: ['/home/airflow/.local/lib/python3.7/site-packages/tensorflow_io/python/ops/libtensorflow_io.so: cannot open shared object file: No such file or directory']
[2023-05-07T23:30:37.099+0000] {processor.py:811} WARNING - No viable dags retrieved from /opt/airflow/dags/utils/fetching_best_model.py
[2023-05-07T23:30:37.110+0000] {processor.py:178} INFO - Processing /opt/airflow/dags/utils/fetching_best_model.py took 1.582 seconds
[2023-05-07T23:31:07.677+0000] {processor.py:156} INFO - Started process (PID=529) to work on /opt/airflow/dags/utils/fetching_best_model.py
[2023-05-07T23:31:07.678+0000] {processor.py:799} INFO - Processing file /opt/airflow/dags/utils/fetching_best_model.py for tasks to queue
[2023-05-07T23:31:07.680+0000] {logging_mixin.py:149} INFO - [2023-05-07T23:31:07.680+0000] {dagbag.py:541} INFO - Filling up the DagBag from /opt/airflow/dags/utils/fetching_best_model.py
[2023-05-07T23:31:09.141+0000] {logging_mixin.py:149} WARNING - /home/airflow/.local/lib/python3.7/site-packages/tensorflow_io/python/ops/__init__.py:98 UserWarning: unable to load libtensorflow_io_plugins.so: unable to open file: libtensorflow_io_plugins.so, from paths: ['/home/airflow/.local/lib/python3.7/site-packages/tensorflow_io/python/ops/libtensorflow_io_plugins.so']
caused by: ["[Errno 2] The file to load file system plugin from does not exist.: '/home/airflow/.local/lib/python3.7/site-packages/tensorflow_io/python/ops/libtensorflow_io_plugins.so'"]
[2023-05-07T23:31:09.144+0000] {logging_mixin.py:149} WARNING - /home/airflow/.local/lib/python3.7/site-packages/tensorflow_io/python/ops/__init__.py:104 UserWarning: file system plugins are not loaded: unable to open file: libtensorflow_io.so, from paths: ['/home/airflow/.local/lib/python3.7/site-packages/tensorflow_io/python/ops/libtensorflow_io.so']
caused by: ['/home/airflow/.local/lib/python3.7/site-packages/tensorflow_io/python/ops/libtensorflow_io.so: cannot open shared object file: No such file or directory']
[2023-05-07T23:31:09.322+0000] {processor.py:811} WARNING - No viable dags retrieved from /opt/airflow/dags/utils/fetching_best_model.py
[2023-05-07T23:31:09.333+0000] {processor.py:178} INFO - Processing /opt/airflow/dags/utils/fetching_best_model.py took 1.661 seconds
[2023-05-07T23:31:39.902+0000] {processor.py:156} INFO - Started process (PID=556) to work on /opt/airflow/dags/utils/fetching_best_model.py
[2023-05-07T23:31:39.904+0000] {processor.py:799} INFO - Processing file /opt/airflow/dags/utils/fetching_best_model.py for tasks to queue
[2023-05-07T23:31:39.905+0000] {logging_mixin.py:149} INFO - [2023-05-07T23:31:39.905+0000] {dagbag.py:541} INFO - Filling up the DagBag from /opt/airflow/dags/utils/fetching_best_model.py
[2023-05-07T23:31:41.221+0000] {logging_mixin.py:149} WARNING - /home/airflow/.local/lib/python3.7/site-packages/tensorflow_io/python/ops/__init__.py:98 UserWarning: unable to load libtensorflow_io_plugins.so: unable to open file: libtensorflow_io_plugins.so, from paths: ['/home/airflow/.local/lib/python3.7/site-packages/tensorflow_io/python/ops/libtensorflow_io_plugins.so']
caused by: ["[Errno 2] The file to load file system plugin from does not exist.: '/home/airflow/.local/lib/python3.7/site-packages/tensorflow_io/python/ops/libtensorflow_io_plugins.so'"]
[2023-05-07T23:31:41.224+0000] {logging_mixin.py:149} WARNING - /home/airflow/.local/lib/python3.7/site-packages/tensorflow_io/python/ops/__init__.py:104 UserWarning: file system plugins are not loaded: unable to open file: libtensorflow_io.so, from paths: ['/home/airflow/.local/lib/python3.7/site-packages/tensorflow_io/python/ops/libtensorflow_io.so']
caused by: ['/home/airflow/.local/lib/python3.7/site-packages/tensorflow_io/python/ops/libtensorflow_io.so: cannot open shared object file: No such file or directory']
[2023-05-07T23:31:41.404+0000] {processor.py:811} WARNING - No viable dags retrieved from /opt/airflow/dags/utils/fetching_best_model.py
[2023-05-07T23:31:41.415+0000] {processor.py:178} INFO - Processing /opt/airflow/dags/utils/fetching_best_model.py took 1.518 seconds
[2023-05-07T23:32:11.833+0000] {processor.py:156} INFO - Started process (PID=581) to work on /opt/airflow/dags/utils/fetching_best_model.py
[2023-05-07T23:32:11.835+0000] {processor.py:799} INFO - Processing file /opt/airflow/dags/utils/fetching_best_model.py for tasks to queue
[2023-05-07T23:32:11.836+0000] {logging_mixin.py:149} INFO - [2023-05-07T23:32:11.836+0000] {dagbag.py:541} INFO - Filling up the DagBag from /opt/airflow/dags/utils/fetching_best_model.py
[2023-05-07T23:32:13.127+0000] {logging_mixin.py:149} WARNING - /home/airflow/.local/lib/python3.7/site-packages/tensorflow_io/python/ops/__init__.py:98 UserWarning: unable to load libtensorflow_io_plugins.so: unable to open file: libtensorflow_io_plugins.so, from paths: ['/home/airflow/.local/lib/python3.7/site-packages/tensorflow_io/python/ops/libtensorflow_io_plugins.so']
caused by: ["[Errno 2] The file to load file system plugin from does not exist.: '/home/airflow/.local/lib/python3.7/site-packages/tensorflow_io/python/ops/libtensorflow_io_plugins.so'"]
[2023-05-07T23:32:13.129+0000] {logging_mixin.py:149} WARNING - /home/airflow/.local/lib/python3.7/site-packages/tensorflow_io/python/ops/__init__.py:104 UserWarning: file system plugins are not loaded: unable to open file: libtensorflow_io.so, from paths: ['/home/airflow/.local/lib/python3.7/site-packages/tensorflow_io/python/ops/libtensorflow_io.so']
caused by: ['/home/airflow/.local/lib/python3.7/site-packages/tensorflow_io/python/ops/libtensorflow_io.so: cannot open shared object file: No such file or directory']
[2023-05-07T23:32:13.295+0000] {processor.py:811} WARNING - No viable dags retrieved from /opt/airflow/dags/utils/fetching_best_model.py
[2023-05-07T23:32:13.306+0000] {processor.py:178} INFO - Processing /opt/airflow/dags/utils/fetching_best_model.py took 1.478 seconds
[2023-05-07T23:32:43.737+0000] {processor.py:156} INFO - Started process (PID=615) to work on /opt/airflow/dags/utils/fetching_best_model.py
[2023-05-07T23:32:43.740+0000] {processor.py:799} INFO - Processing file /opt/airflow/dags/utils/fetching_best_model.py for tasks to queue
[2023-05-07T23:32:43.741+0000] {logging_mixin.py:149} INFO - [2023-05-07T23:32:43.741+0000] {dagbag.py:541} INFO - Filling up the DagBag from /opt/airflow/dags/utils/fetching_best_model.py
[2023-05-07T23:32:44.955+0000] {logging_mixin.py:149} WARNING - /home/airflow/.local/lib/python3.7/site-packages/tensorflow_io/python/ops/__init__.py:98 UserWarning: unable to load libtensorflow_io_plugins.so: unable to open file: libtensorflow_io_plugins.so, from paths: ['/home/airflow/.local/lib/python3.7/site-packages/tensorflow_io/python/ops/libtensorflow_io_plugins.so']
caused by: ["[Errno 2] The file to load file system plugin from does not exist.: '/home/airflow/.local/lib/python3.7/site-packages/tensorflow_io/python/ops/libtensorflow_io_plugins.so'"]
[2023-05-07T23:32:44.957+0000] {logging_mixin.py:149} WARNING - /home/airflow/.local/lib/python3.7/site-packages/tensorflow_io/python/ops/__init__.py:104 UserWarning: file system plugins are not loaded: unable to open file: libtensorflow_io.so, from paths: ['/home/airflow/.local/lib/python3.7/site-packages/tensorflow_io/python/ops/libtensorflow_io.so']
caused by: ['/home/airflow/.local/lib/python3.7/site-packages/tensorflow_io/python/ops/libtensorflow_io.so: cannot open shared object file: No such file or directory']
[2023-05-07T23:32:45.103+0000] {processor.py:811} WARNING - No viable dags retrieved from /opt/airflow/dags/utils/fetching_best_model.py
[2023-05-07T23:32:45.113+0000] {processor.py:178} INFO - Processing /opt/airflow/dags/utils/fetching_best_model.py took 1.381 seconds
[2023-05-07T23:33:15.443+0000] {processor.py:156} INFO - Started process (PID=667) to work on /opt/airflow/dags/utils/fetching_best_model.py
[2023-05-07T23:33:15.445+0000] {processor.py:799} INFO - Processing file /opt/airflow/dags/utils/fetching_best_model.py for tasks to queue
[2023-05-07T23:33:15.446+0000] {logging_mixin.py:149} INFO - [2023-05-07T23:33:15.446+0000] {dagbag.py:541} INFO - Filling up the DagBag from /opt/airflow/dags/utils/fetching_best_model.py
[2023-05-07T23:33:16.949+0000] {logging_mixin.py:149} WARNING - /home/airflow/.local/lib/python3.7/site-packages/tensorflow_io/python/ops/__init__.py:98 UserWarning: unable to load libtensorflow_io_plugins.so: unable to open file: libtensorflow_io_plugins.so, from paths: ['/home/airflow/.local/lib/python3.7/site-packages/tensorflow_io/python/ops/libtensorflow_io_plugins.so']
caused by: ["[Errno 2] The file to load file system plugin from does not exist.: '/home/airflow/.local/lib/python3.7/site-packages/tensorflow_io/python/ops/libtensorflow_io_plugins.so'"]
[2023-05-07T23:33:16.951+0000] {logging_mixin.py:149} WARNING - /home/airflow/.local/lib/python3.7/site-packages/tensorflow_io/python/ops/__init__.py:104 UserWarning: file system plugins are not loaded: unable to open file: libtensorflow_io.so, from paths: ['/home/airflow/.local/lib/python3.7/site-packages/tensorflow_io/python/ops/libtensorflow_io.so']
caused by: ['/home/airflow/.local/lib/python3.7/site-packages/tensorflow_io/python/ops/libtensorflow_io.so: cannot open shared object file: No such file or directory']
[2023-05-07T23:33:17.125+0000] {processor.py:811} WARNING - No viable dags retrieved from /opt/airflow/dags/utils/fetching_best_model.py
[2023-05-07T23:33:17.135+0000] {processor.py:178} INFO - Processing /opt/airflow/dags/utils/fetching_best_model.py took 1.698 seconds
[2023-05-07T23:33:47.547+0000] {processor.py:156} INFO - Started process (PID=692) to work on /opt/airflow/dags/utils/fetching_best_model.py
[2023-05-07T23:33:47.549+0000] {processor.py:799} INFO - Processing file /opt/airflow/dags/utils/fetching_best_model.py for tasks to queue
[2023-05-07T23:33:47.550+0000] {logging_mixin.py:149} INFO - [2023-05-07T23:33:47.550+0000] {dagbag.py:541} INFO - Filling up the DagBag from /opt/airflow/dags/utils/fetching_best_model.py
[2023-05-07T23:33:48.773+0000] {logging_mixin.py:149} WARNING - /home/airflow/.local/lib/python3.7/site-packages/tensorflow_io/python/ops/__init__.py:98 UserWarning: unable to load libtensorflow_io_plugins.so: unable to open file: libtensorflow_io_plugins.so, from paths: ['/home/airflow/.local/lib/python3.7/site-packages/tensorflow_io/python/ops/libtensorflow_io_plugins.so']
caused by: ["[Errno 2] The file to load file system plugin from does not exist.: '/home/airflow/.local/lib/python3.7/site-packages/tensorflow_io/python/ops/libtensorflow_io_plugins.so'"]
[2023-05-07T23:33:48.776+0000] {logging_mixin.py:149} WARNING - /home/airflow/.local/lib/python3.7/site-packages/tensorflow_io/python/ops/__init__.py:104 UserWarning: file system plugins are not loaded: unable to open file: libtensorflow_io.so, from paths: ['/home/airflow/.local/lib/python3.7/site-packages/tensorflow_io/python/ops/libtensorflow_io.so']
caused by: ['/home/airflow/.local/lib/python3.7/site-packages/tensorflow_io/python/ops/libtensorflow_io.so: cannot open shared object file: No such file or directory']
[2023-05-07T23:33:48.926+0000] {processor.py:811} WARNING - No viable dags retrieved from /opt/airflow/dags/utils/fetching_best_model.py
[2023-05-07T23:33:48.936+0000] {processor.py:178} INFO - Processing /opt/airflow/dags/utils/fetching_best_model.py took 1.395 seconds
[2023-05-07T23:34:19.324+0000] {processor.py:156} INFO - Started process (PID=717) to work on /opt/airflow/dags/utils/fetching_best_model.py
[2023-05-07T23:34:19.326+0000] {processor.py:799} INFO - Processing file /opt/airflow/dags/utils/fetching_best_model.py for tasks to queue
[2023-05-07T23:34:19.328+0000] {logging_mixin.py:149} INFO - [2023-05-07T23:34:19.327+0000] {dagbag.py:541} INFO - Filling up the DagBag from /opt/airflow/dags/utils/fetching_best_model.py
[2023-05-07T23:34:20.518+0000] {logging_mixin.py:149} WARNING - /home/airflow/.local/lib/python3.7/site-packages/tensorflow_io/python/ops/__init__.py:98 UserWarning: unable to load libtensorflow_io_plugins.so: unable to open file: libtensorflow_io_plugins.so, from paths: ['/home/airflow/.local/lib/python3.7/site-packages/tensorflow_io/python/ops/libtensorflow_io_plugins.so']
caused by: ["[Errno 2] The file to load file system plugin from does not exist.: '/home/airflow/.local/lib/python3.7/site-packages/tensorflow_io/python/ops/libtensorflow_io_plugins.so'"]
[2023-05-07T23:34:20.520+0000] {logging_mixin.py:149} WARNING - /home/airflow/.local/lib/python3.7/site-packages/tensorflow_io/python/ops/__init__.py:104 UserWarning: file system plugins are not loaded: unable to open file: libtensorflow_io.so, from paths: ['/home/airflow/.local/lib/python3.7/site-packages/tensorflow_io/python/ops/libtensorflow_io.so']
caused by: ['/home/airflow/.local/lib/python3.7/site-packages/tensorflow_io/python/ops/libtensorflow_io.so: cannot open shared object file: No such file or directory']
[2023-05-07T23:34:20.676+0000] {processor.py:811} WARNING - No viable dags retrieved from /opt/airflow/dags/utils/fetching_best_model.py
[2023-05-07T23:34:20.686+0000] {processor.py:178} INFO - Processing /opt/airflow/dags/utils/fetching_best_model.py took 1.367 seconds
[2023-05-07T23:34:51.109+0000] {processor.py:156} INFO - Started process (PID=742) to work on /opt/airflow/dags/utils/fetching_best_model.py
[2023-05-07T23:34:51.111+0000] {processor.py:799} INFO - Processing file /opt/airflow/dags/utils/fetching_best_model.py for tasks to queue
[2023-05-07T23:34:51.113+0000] {logging_mixin.py:149} INFO - [2023-05-07T23:34:51.113+0000] {dagbag.py:541} INFO - Filling up the DagBag from /opt/airflow/dags/utils/fetching_best_model.py
[2023-05-07T23:34:52.359+0000] {logging_mixin.py:149} WARNING - /home/airflow/.local/lib/python3.7/site-packages/tensorflow_io/python/ops/__init__.py:98 UserWarning: unable to load libtensorflow_io_plugins.so: unable to open file: libtensorflow_io_plugins.so, from paths: ['/home/airflow/.local/lib/python3.7/site-packages/tensorflow_io/python/ops/libtensorflow_io_plugins.so']
caused by: ["[Errno 2] The file to load file system plugin from does not exist.: '/home/airflow/.local/lib/python3.7/site-packages/tensorflow_io/python/ops/libtensorflow_io_plugins.so'"]
[2023-05-07T23:34:52.361+0000] {logging_mixin.py:149} WARNING - /home/airflow/.local/lib/python3.7/site-packages/tensorflow_io/python/ops/__init__.py:104 UserWarning: file system plugins are not loaded: unable to open file: libtensorflow_io.so, from paths: ['/home/airflow/.local/lib/python3.7/site-packages/tensorflow_io/python/ops/libtensorflow_io.so']
caused by: ['/home/airflow/.local/lib/python3.7/site-packages/tensorflow_io/python/ops/libtensorflow_io.so: cannot open shared object file: No such file or directory']
[2023-05-07T23:34:52.505+0000] {processor.py:811} WARNING - No viable dags retrieved from /opt/airflow/dags/utils/fetching_best_model.py
[2023-05-07T23:34:52.515+0000] {processor.py:178} INFO - Processing /opt/airflow/dags/utils/fetching_best_model.py took 1.412 seconds
[2023-05-07T23:34:53.141+0000] {processor.py:156} INFO - Started process (PID=751) to work on /opt/airflow/dags/utils/fetching_best_model.py
[2023-05-07T23:34:53.143+0000] {processor.py:799} INFO - Processing file /opt/airflow/dags/utils/fetching_best_model.py for tasks to queue
[2023-05-07T23:34:53.145+0000] {logging_mixin.py:149} INFO - [2023-05-07T23:34:53.145+0000] {dagbag.py:541} INFO - Filling up the DagBag from /opt/airflow/dags/utils/fetching_best_model.py
[2023-05-07T23:34:54.354+0000] {logging_mixin.py:149} WARNING - /home/airflow/.local/lib/python3.7/site-packages/tensorflow_io/python/ops/__init__.py:98 UserWarning: unable to load libtensorflow_io_plugins.so: unable to open file: libtensorflow_io_plugins.so, from paths: ['/home/airflow/.local/lib/python3.7/site-packages/tensorflow_io/python/ops/libtensorflow_io_plugins.so']
caused by: ["[Errno 2] The file to load file system plugin from does not exist.: '/home/airflow/.local/lib/python3.7/site-packages/tensorflow_io/python/ops/libtensorflow_io_plugins.so'"]
[2023-05-07T23:34:54.357+0000] {logging_mixin.py:149} WARNING - /home/airflow/.local/lib/python3.7/site-packages/tensorflow_io/python/ops/__init__.py:104 UserWarning: file system plugins are not loaded: unable to open file: libtensorflow_io.so, from paths: ['/home/airflow/.local/lib/python3.7/site-packages/tensorflow_io/python/ops/libtensorflow_io.so']
caused by: ['/home/airflow/.local/lib/python3.7/site-packages/tensorflow_io/python/ops/libtensorflow_io.so: cannot open shared object file: No such file or directory']
[2023-05-07T23:34:54.501+0000] {processor.py:811} WARNING - No viable dags retrieved from /opt/airflow/dags/utils/fetching_best_model.py
[2023-05-07T23:34:54.510+0000] {processor.py:178} INFO - Processing /opt/airflow/dags/utils/fetching_best_model.py took 1.375 seconds
[2023-05-07T23:34:56.622+0000] {processor.py:156} INFO - Started process (PID=760) to work on /opt/airflow/dags/utils/fetching_best_model.py
[2023-05-07T23:34:56.624+0000] {processor.py:799} INFO - Processing file /opt/airflow/dags/utils/fetching_best_model.py for tasks to queue
[2023-05-07T23:34:56.626+0000] {logging_mixin.py:149} INFO - [2023-05-07T23:34:56.625+0000] {dagbag.py:541} INFO - Filling up the DagBag from /opt/airflow/dags/utils/fetching_best_model.py
[2023-05-07T23:34:57.872+0000] {logging_mixin.py:149} WARNING - /home/airflow/.local/lib/python3.7/site-packages/tensorflow_io/python/ops/__init__.py:98 UserWarning: unable to load libtensorflow_io_plugins.so: unable to open file: libtensorflow_io_plugins.so, from paths: ['/home/airflow/.local/lib/python3.7/site-packages/tensorflow_io/python/ops/libtensorflow_io_plugins.so']
caused by: ["[Errno 2] The file to load file system plugin from does not exist.: '/home/airflow/.local/lib/python3.7/site-packages/tensorflow_io/python/ops/libtensorflow_io_plugins.so'"]
[2023-05-07T23:34:57.874+0000] {logging_mixin.py:149} WARNING - /home/airflow/.local/lib/python3.7/site-packages/tensorflow_io/python/ops/__init__.py:104 UserWarning: file system plugins are not loaded: unable to open file: libtensorflow_io.so, from paths: ['/home/airflow/.local/lib/python3.7/site-packages/tensorflow_io/python/ops/libtensorflow_io.so']
caused by: ['/home/airflow/.local/lib/python3.7/site-packages/tensorflow_io/python/ops/libtensorflow_io.so: cannot open shared object file: No such file or directory']
[2023-05-07T23:34:58.021+0000] {processor.py:811} WARNING - No viable dags retrieved from /opt/airflow/dags/utils/fetching_best_model.py
[2023-05-07T23:34:58.030+0000] {processor.py:178} INFO - Processing /opt/airflow/dags/utils/fetching_best_model.py took 1.414 seconds
[2023-05-07T23:35:24.424+0000] {processor.py:156} INFO - Started process (PID=786) to work on /opt/airflow/dags/utils/fetching_best_model.py
[2023-05-07T23:35:24.426+0000] {processor.py:799} INFO - Processing file /opt/airflow/dags/utils/fetching_best_model.py for tasks to queue
[2023-05-07T23:35:24.427+0000] {logging_mixin.py:149} INFO - [2023-05-07T23:35:24.427+0000] {dagbag.py:541} INFO - Filling up the DagBag from /opt/airflow/dags/utils/fetching_best_model.py
[2023-05-07T23:35:24.430+0000] {logging_mixin.py:149} INFO - [2023-05-07T23:35:24.430+0000] {dagbag.py:327} INFO - File /opt/airflow/dags/utils/fetching_best_model.py assumed to contain no DAGs. Skipping.
[2023-05-07T23:35:24.431+0000] {processor.py:811} WARNING - No viable dags retrieved from /opt/airflow/dags/utils/fetching_best_model.py
[2023-05-07T23:35:24.449+0000] {processor.py:178} INFO - Processing /opt/airflow/dags/utils/fetching_best_model.py took 0.029 seconds
[2023-05-07T23:35:44.673+0000] {processor.py:156} INFO - Started process (PID=796) to work on /opt/airflow/dags/utils/fetching_best_model.py
[2023-05-07T23:35:44.675+0000] {processor.py:799} INFO - Processing file /opt/airflow/dags/utils/fetching_best_model.py for tasks to queue
[2023-05-07T23:35:44.677+0000] {logging_mixin.py:149} INFO - [2023-05-07T23:35:44.676+0000] {dagbag.py:541} INFO - Filling up the DagBag from /opt/airflow/dags/utils/fetching_best_model.py
[2023-05-07T23:35:44.681+0000] {logging_mixin.py:149} INFO - [2023-05-07T23:35:44.681+0000] {dagbag.py:327} INFO - File /opt/airflow/dags/utils/fetching_best_model.py assumed to contain no DAGs. Skipping.
[2023-05-07T23:35:44.682+0000] {processor.py:811} WARNING - No viable dags retrieved from /opt/airflow/dags/utils/fetching_best_model.py
[2023-05-07T23:35:44.703+0000] {processor.py:178} INFO - Processing /opt/airflow/dags/utils/fetching_best_model.py took 0.036 seconds
[2023-05-07T23:36:14.996+0000] {processor.py:156} INFO - Started process (PID=831) to work on /opt/airflow/dags/utils/fetching_best_model.py
[2023-05-07T23:36:14.999+0000] {processor.py:799} INFO - Processing file /opt/airflow/dags/utils/fetching_best_model.py for tasks to queue
[2023-05-07T23:36:15.004+0000] {logging_mixin.py:149} INFO - [2023-05-07T23:36:15.004+0000] {dagbag.py:541} INFO - Filling up the DagBag from /opt/airflow/dags/utils/fetching_best_model.py
[2023-05-07T23:36:15.007+0000] {logging_mixin.py:149} INFO - [2023-05-07T23:36:15.007+0000] {dagbag.py:327} INFO - File /opt/airflow/dags/utils/fetching_best_model.py assumed to contain no DAGs. Skipping.
[2023-05-07T23:36:15.009+0000] {processor.py:811} WARNING - No viable dags retrieved from /opt/airflow/dags/utils/fetching_best_model.py
[2023-05-07T23:36:15.048+0000] {processor.py:178} INFO - Processing /opt/airflow/dags/utils/fetching_best_model.py took 0.061 seconds
